Workbook

Sheet Trimestre contra Trimestre Ant.
A1: TRIMESTRE CONTRA TRIMESTRE IMEDIATAMENTE ANTERIOR (%)
A2: Com ajuste sazonal
A3: Período | B3: AGROPECUÁRIA | C3: INDÚSTRIA | H3: SERVIÇOS | P3: VA | Q3: PIB | R3: Consumo das Famílias | S3: Consumo do Governo | T3: Formação Bruta de Capital Fixo | U3: Exportação | V3: Importação
B4: Total | C4: Indústrias extrativas | D4: Indústrias de transformação | E4: Eletricidade e gás, água, esgoto, ativ. de gestão de resíduos | F4: Construção | G4: Total | H4: Comércio | I4: Transporte, armazenagem e correio | J4: Informação e comunicação | K4: Atividades financeiras, de seguros e serviços relacionados | L4: Atividades Imobiliárias | M4: Outras atividades de serviços | N4: Adm., defesa, saúde e educação públicas e seguridade social | O4: Total
A5: 1996.I
A6: 1996.II | B6: 1.4056204 | C6: -0.42489475 | D6: -5.0751008 | E6: 0.6464082 | F6: -0.95181231 | G6: -3.6926725 | H6: 1.7965925 | I6: -1.4493752 | J6: 1.4164885 | K6: -0.89047016 | L6: 0.64842856 | M6: -0.50966031 | N6: 2.0364448 | O6: 0.26049221 | P6: 0.89787228 | Q6: 1.1891662 | R6: 2.0670043 | S6: 1.6092551 | T6: 1.9355389 | U6: -2.8990378 | V6: 9.1330691
A7: 1996.III | B7: 5.3540981 | C7: -4.9559555 | D7: 15.364273 | E7: 0.86606043 | F7: 0.79689141 | G7: 8.9951725 | H7: 2.6222413 | I7: 3.1251889 | J7: 4.1574578 | K7: 0.83773382 | L7: 0.93603732 | M7: 0.28424981 | N7: 0.49424839 | O7: 1.2671723 | P7: 3.6878805 | Q7: 3.69284 | R7: 2.7929375 | S7: 3.4723973 | T7: 3.7446034 | U7: -0.51056506 | V7: 7.3647927
A8: 1996.IV | B8: 23.627056 | C8: 4.768471 | D8: -9.6242662 | E8: 2.2371308 | F8: -0.14229319 | G8: -6.0858562 | H8: 1.3942763 | I8: -3.5753816 | J8: -2.4475933 | K8: -8.0448143 | L8: -2.4023688 | M8: -0.35312821 | N8: -0.6105178 | O8: -2.0665969 | P8: -2.4001376 | Q8: -0.95177098 | R8: 5.2515739 | S8: -15.049974 | T8: 4.2627093 | U8: 3.0935974 | V8: 10.932623
A9: 1997.I | B9: -19.021829 | C9: 1.0919209 | D9: 3.5383569 | E9: 2.407272 | F9: 3.4817398 | G9: 5.0656663 | H9: 0.16045029 | I9: 4.903681 | J9: 1.5410326 | K9: 10.435404 | L9: 2.1912052 | M9: 1.4298879 | N9: 0.15629282 | O9: 2.4583411 | P9: 2.001619 | Q9: 1.0767159 | R9: -2.312387 | S9: 13.282502 | T9: 0.85122326 | U9: 6.3685436 | V9: -0.28102123
A10: 1997.II | B10: -1.4649222 | C10: 1.7928655 | D10: 1.2842817 | E10: -0.89805036 | F10: 2.5181769 | G10: -0.14810229 | H10: 0.57550609 | I10: 2.9430015 | J10: 2.6264477 | K10: -1.2203994 | L10: 0.74777544 | M10: 0.89331544 | N10: -0.78420389 | O10: 0.54732192 | P10: 0.20691569 | Q10: 0.48375147 | R10: 0.27666178 | S10: -0.40321644 | T10: 1.4064721 | U10: 6.4184263 | V10: 4.1554178
A11: 1997.III | B11: 3.246908 | C11: 3.0982488 | D11: 0.47498924 | E11: 2.9457716 | F11: 2.9313347 | G11: 1.881761 | H11: 1.4161338 | I11: 0.55434052 | J11: 0.89119783 | K11: 0.7670352 | L11: 1.113783 | M11: 0.70641592 | N11: 0.33991276 | O11: 0.46818587 | P11: 1.2192382 | Q11: 1.2716514 | R11: -0.96052413 | S11: -1.5693782 | T11: 1.9577167 | U11: 1.974231 | V11: 0.64451195
A12: 1997.IV | B12: 8.6182696 | C12: -0.13140761 | D12: -1.344706 | E12: 1.3251554 | F12: 1.821875 | G12: -0.35615598 | H12: 0.16237599 | I12: 1.9654908 | J12: 2.5347768 | K12: 0.18292075 | L12: 1.5280284 | M12: 2.1765132 | N12: 0.90768783 | O12: 1.2238559 | P12: 0.91719479 | Q12: 0.84076386 | R12: 0.13054578 | S12: 0.7137161 | T12: -0.65264472 | U12: -4.5735943 | V12: -5.9839809
A13: 1998.I | B13: -11.027025 | C13: 1.4874866 | D13: -4.2208336 | E13: -0.54049598 | F13: -1.2812009 | G13: -2.2456869 | H13: -2.3306886 | I13: -3.6634246 | J13: -1.6065024 | K13: -1.7967735 | L13: -0.48914423 | M13: -2.6920641 | N13: 0.85796783 | O13: -0.99850154 | P13: -1.752479 | Q13: -1.9771681 | R13: 0.017047604 | S13: 2.3951709 | T13: 0.5432808 | U13: 5.9880883 | V13: 9.0290072
A14: 1998.II | B14: 12.53657 | C14: 1.7327217 | D14: 1.5903105 | E14: -0.34442963 | F14: 1.2480028 | G14: 1.2827494 | H14: 1.6550506 | I14: 3.7946442 | J14: -0.76075433 | K14: -0.31080995 | L14: 0.91713129 | M14: 1.9176995 | N14: 0.96905223 | O14: 1.1076079 | P14: 1.835143 | Q14: 1.7124215 | R14: -0.30922031 | S14: 0.66769247 | T14: 0.36669941 | U14: 2.6877997 | V14: -5.3882377
A15: 1998.III | B15: -2.6230377 | C15: -1.3750265 | D15: -0.97632831 | E15: 0.045146022 | F15: -1.4888066 | G15: -1.2699203 | H15: -1.1537292 | I15: 0.40640859 | J15: 11.750092 | K15: 0.50749757 | L15: 0.5598759 | M15: 0.35589733 | N15: 0.77106616 | O15: 0.60924949 | P15: -0.080775525 | Q15: -0.02876667 | R15: 0.30750461 | S15: 1.7360796 | T15: -1.2910957 | U15: -4.2635468 | V15: 1.0243691
A16: 1998.IV | B16: -2.0770049 | C16: -1.0416728 | D16: -3.5911782 | E16: -0.78581438 | F16: -2.4471579 | G16: -3.1185236 | H16: -4.2913386 | I16: -3.9909089 | J16: 4.2364204 | K16: 0.37030482 | L16: 0.72936676 | M16: 0.2180194 | N16: 0.93350223 | O16: 0.057832982 | P16: -1.0466852 | Q16: -1.1467992 | R16: -1.3236167 | S16: -0.73944295 | T16: -4.5011696 | U16: 0.36441054 | V16: -5.6571928
A17: 1999.I | B17: 4.2154261 | C17: -0.43534977 | D17: -0.80475519 | E17: -0.046368841 | F17: -3.3213122 | G17: -0.50657993 | H17: 0.84381343 | I17: -2.0217983 | J17: 2.6565151 | K17: -0.16231543 | L17: 1.5326988 | M17: -0.91180616 | N17: 1.4128744 | O17: 0.75649783 | P17: 0.9062423 | Q17: 0.18453375 | R17: 0.3050397 | S17: -1.1346896 | T17: -3.5651365 | U17: 1.8779186 | V17: -9.76306
... A126: 2026.II | B126: 2.8213171 | C126: 3.4066744 | D126: -0.37959622 | E126: -1.0717881 | F126: -0.35722726 | G126: 0.12142255 | H126: 0.048255341 | I126: 1.0702845 | J126: 2.0700852 | K126: -0.25002286 | L126: 0.24575721 | M126: -0.036811192 | N126: -0.35605236 | O126: 0.18578936 | P126: 0.51330198 | Q126: 0.47884015 | R126: -0.44380458 | S126: 0.4215136 | T126: 1.2001045 | U126: -0.75488797 | V126: 1.802764

Sheet Acum. em 4 trimestres
A1: TAXA ACUMULADA EM QUATRO TRIMESTRES (em relação ao mesmo período do ano anterior % )
A2: Em relação ao mesmo período do ano anterior - %
A3: Período | B3: AGROPECUÁRIA | C3: INDÚSTRIA | H3: SERVIÇOS | P3: VA | Q3: Imposto | R3: PIB | S3: Consumo das Famílias | T3: Consumo do Governo | U3: Formação Bruta de Capital Fixo | V3: Exportação | W3: Importação
B4: Total | C4: Indústrias extrativas | D4: Indústrias de transformação | E4: Eletricidade e gás, água, esgoto, ativ. de gestão de resíduos | F4: Construção | G4: Total | H4: Comércio | I4: Transporte, armazenagem e correio | J4: Informação e comunicação | K4: Atividades financeiras, de seguros e serviços relacionados | L4: Atividades Imobiliárias | M4: Outras atividades de serviços | N4: Adm., defesa, saúde e educação públicas e seguridade social | O4: Total
A5: 1996.I | B5: -1.9392683 | C5: 2.3086172 | D5: 1.2947563 | E5: 0.35330238 | F5: -6.2399908 | G5: -0.64066569 | H5: 2.9330482 | I5: 9.4464267 | J5: 8.4233497 | K5: 9.6517963 | L5: 1.6647335 | M5: 2.8500363 | N5: 2.8666354 | O5: 5.1577255 | P5: 3.1179752 | Q5: -1.8678772 | R5: 2.5196866 | S5: 2.4902088 | T5: -0.16449651 | U5: -9.1630448 | V5: 11.214702 | W5: -1.9413575
A6: 1996.II | B6: -1.6905568 | C6: 6.4502671 | D6: -2.5695721 | E6: 2.1492124 | F6: -4.4321231 | G6: -2.2684924 | H6: 0.37274615 | I6: 8.7780831 | J6: 8.2064468 | K6: 11.872414 | L6: 1.9799699 | M6: 1.8565951 | N6: 2.927223 | O6: 5.3777404 | P6: 2.8288523 | Q6: -2.9700037 | R6: 2.1356122 | S6: 2.5867536 | T6: -0.69596315 | U6: -9.787323 | V6: 7.0274117 | W6: -7.1365615
A7: 1996.III | B7: -3.653437 | C7: 5.4348149 | D7: 0.2609019 | E7: 2.882425 | F7: -0.5292956 | G7: 0.50274181 | H7: 1.3589427 | I7: 6.782862 | J7: 7.0237504 | K7: 6.4933576 | L7: 2.4121801 | M7: 1.4677786 | N7: 3.5860919 | O7: 4.0343154 | P7: 2.5884762 | Q7: 0.28268275 | R7: 2.309147 | S7: 3.3330881 | T7: -0.76561841 | U7: -4.3899793 | V7: 0.62413065 | W7: -2.8008337
A8: 1996.IV | B8: 2.9531711 | C8: 2.4380536 | D8: 0.08022077 | E8: 3.117207 | F8: 2.2140377 | G8: 0.97461659 | H8: 1.813372 | I8: 5.6181011 | J8: 5.9636196 | K8: 0.88067666 | L8: 2.3860974 | M8: -0.027876507 | N8: 4.3126067 | O8: 2.2991377 | P8: 1.9790592 | Q8: 3.6831528 | R8: 2.2088641 | S8: 3.2365808 | T8: -1.8257396 | U8: 1.1955211 | V8: -0.41986447 | W8: 5.5943152
A9: 1997.I | B9: 4.0956496 | C9: 1.6689031 | D9: 2.5766165 | E9: 3.942278 | F9: 4.8254706 | G9: 3.2773883 | H9: 4.0569004 | I9: 4.6849768 | J9: 5.2895183 | K9: 0.45991301 | L9: 1.9608273 | M9: 0.25944364 | N9: 3.2893238 | O9: 2.105901 | P9: 2.5307922 | Q9: 7.5512526 | R9: 3.1778325 | S9: 5.4520213 | T9: -0.72613477 | U9: 7.4286228 | V9: -1.589057 | W9: 15.839967
A10: 1997.II | B10: 4.6706724 | C10: 0.98106788 | D10: 6.3502632 | E10: 4.5263586 | F10: 6.5445832 | G10: 6.0831953 | H10: 5.5095425 | I10: 5.1255768 | J10: 5.1256282 | K10: 0.015119658 | L10: 1.5804759 | M10: 0.91784529 | N10: 1.9143581 | O10: 1.7646255 | P10: 3.0474948 | Q10: 10.847858 | R10: 4.0228433 | S10: 6.4732685 | T10: -0.86766885 | U10: 11.467143 | V10: 0.9901604 | W10: 24.1773
A11: 1997.III | B11: 5.2349244 | C11: 3.3541194 | D11: 1.3306597 | E11: 5.4653775 | F11: 6.4228983 | G11: 3.1440225 | H11: 4.3959857 | I11: 4.2395146 | J11: 4.5160102 | K11: -0.44018335 | L11: 1.3075134 | M11: 1.2654976 | N11: 0.58067139 | O11: 1.2758239 | P11: 1.9648024 | Q11: 10.285117 | R11: 3.0255588 | S11: 5.6004507 | T11: -3.0717428 | U11: 11.000093 | V11: 6.6092356 | W11: 24.079648
A12: 1997.IV | B12: 0.81302798 | C12: 4.997782 | D12: 2.4934078 | E12: 5.9046728 | F12: 7.6055432 | G12: 4.3749925 | H12: 3.8542985 | I12: 6.1355717 | J12: 5.238603 | K12: 3.3286013 | L12: 2.5060091 | M12: 2.8164643 | N12: -0.042202996 | O12: 2.5342338 | P12: 2.9107215 | Q12: 6.7613546 | R12: 3.394846 | S12: 3.0329739 | T12: 1.2464329 | U12: 8.4181144 | V12: 11.019289 | W12: 14.595077
A13: 1998.I | B13: -1.3340594 | C13: 7.1061653 | D13: 0.89822312 | E13: 5.415092 | F13: 8.3068492 | G13: 3.6061108 | H13: 2.9185419 | I13: 6.5334127 | J13: 5.1886163 | K13: 2.4206075 | L13: 2.9011409 | M13: 2.848082 | N13: 0.16150579 | O13: 2.4055865 | P13: 2.5035432 | Q13: 5.0109891 | R13: 2.8134774 | S13: 1.0513803 | T13: 1.243576 | U13: 6.5549843 | V13: 13.62871 | W13: 10.621462
A14: 1998.II | B14: 0.98311107 | C14: 7.413165 | D14: -2.1589032 | E14: 4.6853435 | F14: 7.7650589 | G14: 1.5699458 | H14: 1.7046875 | I14: 4.8290322 | J14: 3.982146 | K14: 1.7983335 | L14: 3.314748 | M14: 2.8046955 | N14: 1.0294187 | O14: 2.3088164 | P14: 2.0409778 | Q14: 1.9454345 | R14: 2.0194318 | S14: -0.63235191 | T14: 2.0183044 | U14: 4.4129154 | V14: 10.893407 | W14: 4.5120543
A15: 1998.III | B15: 1.9468343 | C15: 5.0081448 | D15: -2.1848646 | E15: 3.134327 | F15: 5.3541317 | G15: 0.78163842 | H15: 0.24513417 | I15: 4.2134024 | J15: 6.3389168 | K15: 1.1603605 | L15: 3.5385897 | M15: 2.5342781 | N15: 2.1526665 | O15: 2.4413181 | P15: 2.0056859 | Q15: -0.6930035 | R15: 1.6430603 | S15: -1.1240628 | T15: 4.9749242 | U15: 1.945327 | V15: 6.0574425 | W15: 0.038000926
A16: 1998.IV | B16: 3.4088881 | C16: 3.6165577 | D16: -4.8411443 | E16: 1.2427167 | F16: 1.5963242 | G16: -2.0900044 | H16: -1.8705087 | I16: 0.68455425 | J16: 7.9436115 | K16: -1.4840004 | L16: 2.5708672 | M16: 1.0980734 | N16: 2.8931569 | O16: 1.4214815 | P16: 0.62466738 | Q16: -1.740725 | R16: 0.3380979 | S16: -0.72001366 | T16: 3.2217667 | U16: -0.16384079 | V16: 4.9082053 | W16: -0.056661237
... A126: 2026.II | B126: 6.1901245 | C126: 12.2428 | D126: -1.1022948 | E126: -0.56850251 | F126: 0.3085819 | G126: 1.3671576 | H126: 0.76461944 | I126: 1.9789319 | J126: 7.0922899 | K126: 2.1910618 | L126: 2.2506921 | M126: 1.6648739 | N126: 0.78698206 | O126: 1.7270866 | P126: 1.889471 | Q126: 1.691615 | R126: 1.8728163 | S126: 0.87306005 | T126: 2.8223734 | U126: -0.18749719 | V126: 8.0417837 | W126: 2.1495559

Sheet Taxa Trimestral
A1: TAXA TRIMESTRAL
A2: Variação em volume em relação ao mesmo trimestre do ano anterior - %
A3: Período | B3: AGROPECUÁRIA | C3: INDÚSTRIA | H3: SERVIÇOS | P3: VA | Q3: Imposto | R3: PIB | S3: Consumo das Famílias | T3: Consumo do Governo | U3: Formação Bruta de Capital Fixo | V3: Exportação | W3: Importação
B4: Total | C4: Indústrias extrativas | D4: Indústrias de transformação | E4: Eletricidade e gás, água, esgoto, ativ. de gestão de resíduos | F4: Construção | G4: Total | H4: Comércio | I4: Transporte, armazenagem e correio | J4: Informação e comunicação | K4: Atividades financeiras, de seguros e serviços relacionados | L4: Atividades Imobiliárias | M4: Outras atividades de serviços | N4: Adm., defesa, saúde e educação públicas e seguridade social | O4: Total
A5: 1996.I | B5: 2.5973826 | C5: 2.1531192 | D5: -7.5763159 | E5: 2.435998 | F5: -6.6822537 | G5: -6.008873 | H5: -4.8100774 | I5: 4.8963854 | J5: 7.4943742 | K5: 3.5650247 | L5: 3.0606288 | M5: -0.31632806 | N5: 4.7495141 | O5: 2.7167606 | P5: 0.29716929 | Q5: -6.5510195 | R5: -0.57987261 | S5: -1.2461874 | T5: -3.2578247 | U5: -12.661424 | V5: 4.7117725 | W5: -16.198831
A6: 1996.II | B6: 2.1608387 | C6: 6.7754178 | D6: -5.5481659 | E6: 2.9183625 | F6: 0.1241511 | G6: -2.9808055 | H6: -0.27872482 | I6: 6.691564 | J6: 6.6236183 | K6: 3.1928788 | L6: 2.9246176 | M6: -0.40232423 | N6: 4.8187614 | O6: 3.6837627 | P6: 1.7441852 | Q6: -1.6504355 | R6: 1.3471927 | S6: 1.8256413 | T6: -0.23172633 | U6: -4.0699731 | V6: 4.5250635 | W6: -6.6103265
A7: 1996.III | B7: -0.60096791 | C7: 1.6228057 | D7: 13.731157 | E7: 2.9826723 | F7: 9.6817038 | G7: 11.346999 | H7: 7.5367346 | I7: 7.8524837 | J7: 5.055919 | K7: 2.8321914 | L7: 2.7235877 | M7: 1.2954632 | N7: 4.4511641 | O7: 3.20869 | P7: 5.1127931 | Q7: 9.894499 | R7: 5.6472133 | S7: 5.3853482 | T7: 2.7650927 | U7: 10.126797 | V7: -3.6480353 | W7: 15.025771
A8: 1996.IV | B8: 8.8704437 | C8: -0.300246 | D8: -0.60351675 | E8: 4.1052856 | F8: 6.4874812 | G8: 1.493972 | H8: 4.4389108 | I8: 3.0328639 | J8: 4.8855724 | K8: -5.0386434 | L8: 0.85189346 | M8: -0.67667832 | N8: 3.2367331 | O8: -0.25294915 | P8: 0.66826459 | Q8: 13.276343 | R8: 2.2744835 | S8: 6.6597965 | T8: -6.7829032 | U8: 13.898074 | V8: -6.5638707 | W8: 31.042743
A9: 1997.I | B9: 6.9742314 | C9: -0.92216048 | D9: 2.740075 | E9: 5.6853813 | F9: 3.1759419 | G9: 3.2818395 | H9: 4.5593338 | I9: 1.0356738 | J9: 4.6679442 | K9: 1.6906494 | L9: 1.3625565 | M9: 0.86854307 | N9: 0.71014643 | O9: 1.9143999 | P9: 2.5711533 | Q9: 8.9793274 | R9: 3.4005717 | S9: 7.8942946 | T9: 1.2330078 | U9: 11.260826 | V9: -0.48635072 | W9: 27.543701
A10: 1997.II | B10: 4.4085455 | C10: 3.6400265 | D10: 9.1783773 | E10: 5.2913471 | F10: 6.8203395 | G10: 8.0337367 | H10: 5.4196061 | I10: 8.3243751 | J10: 5.8869184 | K10: 1.1539614 | L10: 1.3959755 | M10: 2.2651828 | N10: -0.59206147 | O10: 2.2495651 | P10: 3.8318653 | Q10: 11.114249 | R10: 4.7540023 | S10: 5.9917178 | T10: -0.79142139 | U10: 10.698806 | V10: 14.337372 | W10: 23.824245
A11: 1997.III | B11: 1.4772805 | C11: 11.202796 | D11: -4.6279544 | E11: 6.7788729 | F11: 8.9484491 | G11: 0.21397621 | H11: 3.2729455 | I11: 4.3911944 | J11: 2.6850618 | K11: 1.0557897 | L11: 1.6100939 | M11: 2.6642633 | N11: -0.90023626 | O11: 1.2712096 | P11: 0.90983076 | Q11: 7.8908967 | R11: 1.7912794 | S11: 2.0582948 | T11: -5.7157601 | U11: 8.511062 | V11: 17.497994 | W11: 15.886615
A12: 1997.IV | B12: -11.02988 | C12: 5.9265168 | D12: 4.0635719 | E12: 5.8589736 | F12: 11.191718 | G12: 6.4315359 | H12: 2.3663353 | I12: 10.436201 | J12: 7.6070772 | K12: 9.0364491 | L12: 5.6885971 | M12: 5.3199544 | N12: 0.64215323 | O12: 4.6685657 | P12: 4.424305 | Q12: -0.010567904 | R12: 3.738518 | S12: -2.8397277 | T12: 11.476993 | U12: 3.6314129 | V12: 11.635394 | W12: -1.9854469
A13: 1998.I | B13: -1.4151551 | C13: 7.6899984 | D13: -4.2485567 | E13: 3.8103134 | F13: 6.1758733 | G13: 0.065532786 | H13: 0.50054069 | I13: 2.808314 | J13: 4.4905217 | K13: -2.0810138 | L13: 2.9462496 | M13: 1.0150162 | N13: 1.5255225 | O13: 1.3982355 | P13: 0.90580425 | Q13: 1.5405871 | R13: 1.0075748 | S13: -0.50145755 | T13: 1.2216065 | U13: 3.4890502 | V13: 10.420472 | W13: 7.8553828
A14: 1998.II | B14: 13.081073 | C14: 4.9843575 | D14: -3.5156428 | E14: 2.3903184 | F14: 4.8121809 | G14: -0.28143071 | H14: 0.51520007 | I14: 1.5845767 | J14: 1.0696047 | K14: -1.534987 | L14: 3.0521855 | M14: 2.1044562 | N14: 2.8595116 | O14: 1.8640741 | P14: 1.9399987 | Q14: -1.4810651 | R14: 1.5096533 | S14: -1.0797019 | T14: 2.2599265 | U14: 2.1498922 | V14: 4.8092161 | W14: -2.2491282
A15: 1998.III | B15: 5.207556 | C15: 1.7875835 | D15: -4.8437545 | E15: 0.5256954 | F15: 0.019473069 | G15: -2.7083114 | H15: -2.2378868 | I15: 2.1459701 | J15: 12.061296 | K15: -1.2816023 | L15: 2.5227217 | M15: 1.6140029 | N15: 3.5641942 | O15: 1.7972894 | P15: 0.78490424 | Q15: -2.5577779 | R15: 0.3555997 | S15: 0.032241091 | T15: 5.3761198 | U15: -1.208789 | V15: -0.13514998 | W15: -2.0873377
A16: 1998.IV | B16: -5.2939336 | C16: 0.64030728 | D16: -6.7078655 | E16: -1.6154396 | F16: -3.8733841 | G16: -5.1502399 | H16: -5.8878952 | I16: -3.3304731 | J16: 13.465557 | K16: -1.1373077 | L16: 1.7881064 | M16: -0.25364191 | N16: 3.6169998 | O16: 0.65899702 | P16: -1.0700269 | Q16: -4.1173597 | R16: -1.4345374 | S16: -1.3155901 | T16: 3.9749311 | U16: -4.8994758 | V16: 6.0977356 | W16: -2.3925936
... A24: 2000.IV | B24: -1.6294885 | C24: 18.425622 | D24: 5.3330769 | E24: 4.5345915 | F24: 1.4681647 | G24: 4.6937621 | H24: 7.5721796 | I24: 1.4906205 | J24: 17.151355 | K24: 2.322429 | L24: 8.0578839 | M24: 1.7160259 | N24: 2.3433735 | O24: 4.5471062 | P24: 4.4325321 | Q24: 5.364178 | R24: 4.5975118 | S24: 4.084838 | T24: -2.7698631 | U24: 8.8336556 | V24: 2.6751956 | W24: 12.985255
A25: 2001.I | B25: 2.8876747 | C25: 8.9421581 | D25: 4.8139449 | E25: 0.94180185 | F25: 3.5159984 | G25: 4.1115371 | H25: 5.2128328 | I25: 0.50104804 | J25: 10.513598 | K25: 0.075321896 | L25: 4.7145018 | M25: -1.6048103 | N25: 3.0847714 | O25: 2.4243241 | P25: 2.8669349 | Q25: 7.2159888 | R25: 3.4750903 | S25: 4.0243367 | T25: 1.082445 | U25: 10.244422 | V25: 11.186123 | W25: 24.283185 | X25: =AVERAGE(S5:S25) -> 2.114397 | Y25: =AVERAGE(T5:T25) -> 0.90600423 | Z25: =AVERAGE(U5:U25) -> 1.6784059 | AA25: =AVERAGE(V5:V25) -> 7.2146723 | AB25: =AVERAGE(W5:W25) -> 4.5571591
A26: 2001.II | B26: 3.0345477 | C26: 8.6081551 | D26: 0.74783164 | E26: -2.0409705 | F26: -0.2198797 | G26: 0.42885367 | H26: 4.9006004 | I26: -0.4384902 | J26: 7.3212046 | K26: 0.81004112 | L26: 4.2929594 | M26: 0.93715917 | N26: 3.7904658 | O26: 3.1823721 | P26: 2.4941184 | Q26: 1.290097 | R26: 2.3260554 | S26: 3.0913681 | T26: 2.2454493 | U26: 2.0369539 | V26: 13.82371 | W26: 12.826781 | X26: =AVERAGE(S6:S26) -> 2.3209473 | Y26: =AVERAGE(T6:T26) -> 1.1680649 | Z26: =AVERAGE(U6:U26) -> 2.3783286 | AA26: =AVERAGE(V6:V26) -> 7.6485741 | AB26: =AVERAGE(W6:W26) -> 5.9393311
A27: 2001.III | B27: 5.9672658 | C27: 5.1204776 | D27: -0.15553135 | E27: -13.821586 | F27: -4.7669481 | G27: -2.6201625 | H27: 1.1132994 | I27: -0.090114689 | J27: 3.6681893 | K27: 1.3780279 | L27: 2.8202392 | M27: -0.58990525 | N27: 3.9022679 | O27: 1.7323942 | P27: 0.82307002 | Q27: -1.7645307 | R27: 0.46119575 | S27: -1.8256728 | T27: 3.498909 | U27: 1.1936071 | V27: 3.013957 | W27: -5.1981001 | X27: =AVERAGE(S7:S27) -> 2.1470752 | Y27: =AVERAGE(T7:T27) -> 1.3457142 | Z27: =AVERAGE(U7:U27) -> 2.6289753 | AA27: =AVERAGE(V7:V27) -> 7.5766167 | AB27: =AVERAGE(W7:W27) -> 6.0065799
A28: 2001.IV | B28: 11.062489 | C28: 0.2589722 | D28: -1.9260574 | E28: -15.700649 | F28: -4.6341421 | G28: -3.8940035 | H28: -3.1536148 | I28: 0.94475934 | J28: 5.0451939 | K28: 2.1072074 | L28: 0.99377748 | M28: -0.2378156 | N28: 3.4234094 | O28: 1.0089174 | P28: -0.0067379395 | Q28: -3.7663263 | R28: -0.5318018 | S28: -1.8510549 | T28: 3.5966006 | U28: -7.4413581 | V28: 9.764961 | W28: -12.493609 | X28: =AVERAGE(S8:S28) -> 1.8024846 | Y28: =AVERAGE(T8:T28) -> 1.3853098 | Z28: =AVERAGE(U8:U28) -> 1.7923965 | AA28: =AVERAGE(V8:V28) -> 8.2153308 | AB28: =AVERAGE(W8:W28) -> 4.6961333
A29: 2002.I | B29: 4.7146926 | C29: 13.887837 | D29: -2.3006947 | E29: -9.8469114 | F29: -2.4666942 | G29: -2.3258082 | H29: -4.2340839 | I29: 4.6041095 | J29: 7.0110702 | K29: 4.3802523 | L29: 3.0156846 | M29: 4.3673656 | N29: 3.1870616 | O29: 2.9367365 | P29: 1.64909 | Q29: -6.2353546 | R29: 0.47691913 | S29: 0.23811659 | T29: 4.2692785 | U29: -7.9268596 | V29: -4.5753313 | W29: -18.584694 | X29: =AVERAGE(S9:S29) -> 1.4966903 | Y29: =AVERAGE(T9:T29) -> 1.9116042 | Z29: =AVERAGE(U9:U29) -> 0.75311394 | AA29: =AVERAGE(V9:V29) -> 8.3100231 | AB29: =AVERAGE(W9:W29) -> 2.332922
A30: 2002.II | B30: 7.344056 | C30: 20.784198 | D30: 0.6618069 | E30: 0.40271157 | F30: 2.8125651 | G30: 2.31627 | H30: -3.0899818 | I30: 4.3997598 | J30: 4.2476411 | K30: 4.4238581 | L30: 3.2626097 | M30: 3.0430354 | N30: 2.780927 | O30: 2.4859075 | P30: 2.7387762 | Q30: -0.24039828 | R30: 2.2982025 | S30: 0.6953449 | T30: 4.122198 | U30: -4.277079 | V30: -11.07212 | W30: -16.531879 | X30: =AVERAGE(S10:S30) -> 1.1538832 | Y30: =AVERAGE(T10:T30) -> 2.0491847 | Z30: =AVERAGE(U10:U30) -> 0.013213708 | AA30: =AVERAGE(V10:V30) -> 7.8059389 | AB30: =AVERAGE(W10:W30) -> 0.23408486
A31: 2002.III | B31: 11.683817 | C31: 15.821938 | D31: 2.9267283 | E31: 13.577129 | F31: 7.1242601 | G31: 5.7486083 | H31: -1.2885946 | I31: 4.9254337 | J31: 6.3332142 | K31: 4.0299384 | L31: 4.0627253 | M31: 4.7192296 | N31: 2.4144861 | O31: 3.3995968 | P31: 4.5039423 | Q31: 2.3781869 | R31: 4.174709 | S31: 2.7109752 | T31: 4.1796444 | U31: -0.45162664 | V31: 20.140272 | W31: -8.6132133 | X31: =AVERAGE(S11:S31) -> 0.99765734 | Y31: =AVERAGE(T11:T31) -> 2.2859021 | Z31: =AVERAGE(U11:U31) -> -0.51775926 | AA31: =AVERAGE(V11:V31) -> 8.0822674 | AB31: =AVERAGE(W11:W31) -> -1.310556
A32: 2002.IV | B32: 8.7848334 | C32: 10.980896 | D32: 6.6462653 | E32: 16.116083 | F32: 11.779486 | G32: 9.1972109 | H32: -0.97867341 | I32: 2.0022427 | J32: 7.3828831 | K32: 2.581175 | L32: 5.0484626 | M32: 5.74488 | N32: 2.440357 | O32: 3.6311336 | P32: 5.3314599 | Q32: 4.461593 | R32: 5.1726282 | S32: 1.6278146 | T32: 2.7507196 | U32: 7.5965393 | V32: 20.858804 | W32: -8.9966795 | X32: =AVERAGE(S12:S32) -> 0.97715829 | Y32: =AVERAGE(T12:T32) -> 2.6890678 | Z32: =AVERAGE(U12:U32) -> -0.56130796 | AA32: =AVERAGE(V12:V32) -> 8.242306 | AB32: =AVERAGE(W12:W32) -> -2.4954748
A33: 2003.I | B33: 15.371846 | C33: 2.8691761 | D33: -2.6199894 | E33: 9.8913221 | F33: -0.77248562 | G33: 0.069242304 | H33: 0.42245287 | I33: -5.4621701 | J33: 2.994757 | K33: -2.5420766 | L33: 6.8106615 | M33: 2.3524304 | N33: 2.1454604 | O33: 1.8306206 | P33: 2.4474926 | Q33: 3.9309859 | R33: 2.6670284 | S33: -0.017298106 | T33: -0.75047811 | U33: 3.1221299 | V33: 14.664597 | W33: -4.6419319 | X33: =AVERAGE(S13:S33) -> 1.1115597 | Y33: =AVERAGE(T13:T33) -> 2.1068073 | Z33: =AVERAGE(U13:U33) -> -0.58555953 | AA33: =AVERAGE(V13:V33) -> 8.3865538 | AB33: =AVERAGE(W13:W33) -> -2.6219741
A34: 2003.II | B34: 13.434888 | C34: -2.0252171 | D34: 2.0808277 | E34: 0.099959206 | F34: -12.314611 | G34: -1.9913947 | H34: -1.7047271 | I34: -2.8229391 | J34: 4.802508 | K34: -3.8103087 | L34: 5.1407613 | M34: -0.54808142 | N34: 2.9926367 | O34: 0.88887342 | P34: 1.0603284 | Q34: -0.84254288 | R34: 0.78124238 | S34: -2.0397228 | T34: 0.2535281 | U34: -6.8266814 | V34: 27.409337 | W34: -4.1092451 | X34: =AVERAGE(S14:S34) -> 1.038309 | Y34: =AVERAGE(T14:T34) -> 2.0607083 | Z34: =AVERAGE(U14:U34) -> -1.0767848 | AA34: =AVERAGE(V14:V34) -> 9.1955474 | AB34: =AVERAGE(W14:W34) -> -3.1917183
A35: 2003.III | B35: 1.4687258 | C35: 2.5258101 | D35: 7.7030884 | E35: 3.21116 | F35: -12.023103 | G35: 1.9062119 | H35: -3.1644845 | I35: -2.0636257 | J35: 1.827008 | K35: -3.8778324 | L35: 2.653989 | M35: -0.080582166 | N35: 3.5079321 | O35: 0.47002098 | P35: 0.94352272 | Q35: -1.217988 | R35: 0.62618071 | S35: -0.73181201 | T35: 2.0075091 | U35: -6.885549 | V35: 1.5715356 | W35: -3.6939516 | X35: =AVERAGE(S15:S35) -> 1.0548752 | Y35: =AVERAGE(T15:T35) -> 2.0486884 | Z35: =AVERAGE(U15:U35) -> -1.507044 | AA35: =AVERAGE(V15:V35) -> 9.0413721 | AB35: =AVERAGE(W15:W35) -> -3.2605194
A36: 2003.IV | B36: 0.77621901 | C36: 14.426583 | D36: 2.5773218 | E36: 2.0406768 | F36: -9.9614002 | G36: 0.32561996 | H36: 2.9576474 | I36: 1.0154311 | J36: -0.29233717 | K36: -2.6680551 | L36: 1.0479315 | M36: -1.7419146 | N36: 4.1887204 | O36: 0.82503513 | P36: 0.5402448 | Q36: 0.88516564 | R36: 0.58871195 | S36: 0.58959981 | T36: 4.7273271 | U36: -4.8898009 | V36: 5.5536712 | W36: 10.703904 | X36: =AVERAGE(S16:S36) -> 1.081416 | Y36: =AVERAGE(T16:T36) -> 2.0177935 | Z36: =AVERAGE(U16:U36) -> -1.6823302 | AA36: =AVERAGE(V16:V36) -> 9.3122684 | AB36: =AVERAGE(W16:W36) -> -2.6514127
... A126: 2026.II | B126: 6.7643315 | C126: 12.007466 | D126: -0.85553206 | E126: -0.49141994 | F126: 0.95170029 | G126: 1.5017409 | H126: 0.92786745 | I126: 1.1868739 | J126: 8.4234538 | K126: 0.96912915 | L126: 2.2285572 | M126: 1.1216339 | N126: 0.87193788 | O126: 1.5168303 | P126: 1.903103 | Q126: 2.4826862 | R126: 1.9835909 | S126: 0.45530628 | T126: 3.0504653 | U126: 1.4256496 | V126: 3.8463166 | W126: 5.5235997 | X126: =AVERAGE(S106:S126) -> 3.41635 | Y126: =AVERAGE(T106:T126) -> 3.0958402 | Z126: =AVERAGE(U106:U126) -> 3.6103353 | AA126: =AVERAGE(V106:V126) -> 5.942804 | AB126: =AVERAGE(W106:W126) -> 6.5378158

Sheet Série Encadeada
A1: SÉRIE ENCADEADA DO ÍNDICE DE VOLUME TRIMESTRAL
A2: Média de 1995 = 100
A3: Período | B3: AGROPECUÁRIA | C3: INDÚSTRIA | H3: SERVIÇOS | P3: VA | Q3: Imposto | R3: PIB | S3: Consumo das Famílias | T3: Consumo do Governo | U3: Formação Bruta de Capital Fixo | V3: Exportação | W3: Importação
B4: Total | C4: Indústrias extrativas | D4: Indústrias de transformação | E4: Eletricidade e gás, água, esgoto, ativ. de gestão de resíduos | F4: Construção | G4: Total | H4: Comércio | I4: Transporte, armazenagem e correio | J4: Informação e comunicação | K4: Atividades financeiras, de seguros e serviços relacionados | L4: Atividades Imobiliárias | M4: Outras atividades de serviços | N4: Adm., defesa, saúde e educação públicas e seguridade social | O4: Total
A5: 1996.I | B5: 105.32381 | C5: 100.37613 | D5: 89.567522 | E5: 102.6986 | F5: 97.786007 | G5: 93.18826 | H5: 91.409612 | I5: 96.926748 | J5: 100.88655 | K5: 95.222978 | L5: 102.14179 | M5: 96.846911 | N5: 103.01955 | O5: 98.313744 | P5: 97.334612 | Q5: 93.664523 | R5: 96.839684 | S5: 96.062379 | T5: 96.117451 | U5: 92.911094 | V5: 95.16072 | W5: 82.070829
A6: 1996.II | B6: 105.50451 | C6: 99.934292 | D6: 96.05881 | E6: 100.99677 | F6: 101.01443 | G6: 97.90178 | H6: 100.50679 | I6: 102.96393 | J6: 103.64263 | K6: 92.433163 | L6: 102.85115 | M6: 98.456446 | N6: 105.43436 | O6: 100.58297 | P6: 100.14345 | Q6: 99.96561 | R6: 100.11947 | S6: 99.751649 | T6: 100.06826 | U6: 101.18071 | V6: 104.63579 | W6: 98.199785
A7: 1996.III | B7: 108.09604 | C7: 101.47139 | D7: 115.20983 | E7: 102.1912 | F7: 107.35519 | G7: 111.61587 | H7: 108.80373 | I7: 113.86138 | J7: 107.4941 | K7: 109.65936 | L7: 102.98889 | M7: 101.38585 | N7: 105.30668 | O7: 105.75242 | P7: 107.47284 | Q7: 108.13233 | R7: 107.56177 | S7: 104.74096 | T7: 104.99808 | U7: 105.25964 | V7: 106.67333 | W7: 114.4383
A8: 1996.IV | B8: 92.888321 | C8: 107.97042 | D8: 99.484718 | E8: 106.58226 | F8: 102.70053 | G8: 101.19255 | H8: 106.53333 | I8: 108.72035 | J8: 111.8312 | K8: 106.20721 | L8: 101.56257 | M8: 103.19929 | N8: 103.48983 | O8: 104.54742 | P8: 102.96533 | Q8: 112.97015 | R8: 104.31453 | S8: 112.39134 | T8: 91.513253 | U8: 105.43064 | V8: 91.850709 | W8: 127.66835
A9: 1997.I | B9: 112.66934 | C9: 99.450498 | D9: 92.021739 | E9: 108.5374 | F9: 100.89163 | G9: 96.246549 | H9: 95.577281 | I9: 97.930593 | J9: 105.59588 | K9: 96.832865 | L9: 103.53353 | M9: 97.688068 | N9: 103.75114 | O9: 100.19586 | P9: 99.837234 | Q9: 102.07497 | R9: 100.13279 | S9: 103.64583 | T9: 97.302586 | U9: 103.37365 | V9: 94.697905 | W9: 104.67617
A10: 1997.II | B10: 110.15573 | C10: 103.57193 | D10: 104.87545 | E10: 106.34086 | F10: 107.90396 | G10: 105.76695 | H10: 105.95387 | I10: 111.53503 | J10: 109.74399 | K10: 93.499806 | L10: 104.28692 | M10: 100.68666 | N10: 104.81012 | O10: 102.84565 | P10: 103.98081 | Q10: 111.07604 | R10: 104.87915 | S10: 105.72849 | T10: 99.276297 | U10: 112.00584 | V10: 119.63781 | W10: 121.59514
A11: 1997.III | B11: 109.69292 | C11: 112.83902 | D11: 109.87797 | E11: 109.11861 | F11: 116.96181 | G11: 111.8547 | H11: 112.36482 | I11: 118.86125 | J11: 110.38038 | K11: 110.81713 | L11: 104.64711 | M11: 104.08703 | N11: 104.35867 | O11: 107.09675 | P11: 108.45066 | Q11: 116.66494 | R11: 109.48851 | S11: 106.89683 | T11: 98.996641 | U11: 114.21835 | V11: 125.33902 | W11: 132.61867
A12: 1997.IV | B12: 82.642851 | C12: 114.36931 | D12: 103.52735 | E12: 112.82688 | F12: 114.19448 | G12: 107.70079 | H12: 109.05427 | I12: 120.06663 | J12: 120.33828 | K12: 115.80457 | L12: 107.34005 | M12: 108.68944 | N12: 104.1544 | O12: 109.42828 | P12: 107.52083 | Q12: 112.95821 | R12: 108.21435 | S12: 109.19973 | T12: 102.01622 | U12: 109.25927 | V12: 102.5379 | W12: 125.13356
A13: 1998.I | B13: 111.07489 | C13: 107.09824 | D13: 88.112143 | E13: 112.67302 | F13: 107.12257 | G13: 96.309622 | H13: 96.055684 | I13: 100.68079 | J13: 110.33768 | K13: 94.817759 | L13: 106.58388 | M13: 98.679618 | N13: 105.33389 | O13: 101.59684 | P13: 100.74156 | Q13: 103.64752 | R13: 101.1417 | S13: 103.12609 | T13: 98.491241 | U13: 106.98041 | V13: 104.56587 | W13: 112.89889
A14: 1998.II | B14: 124.56528 | C14: 108.73432 | D14: 101.1884 | E14: 108.88275 | F14: 113.09649 | G14: 105.46929 | H14: 106.49974 | I14: 113.30239 | J14: 110.91782 | K14: 92.064596 | L14: 107.46996 | M14: 102.80557 | N14: 107.80718 | O14: 104.76277 | P14: 105.99804 | Q14: 109.43093 | R14: 106.46246 | S14: 104.58693 | T14: 101.51987 | U14: 114.41384 | V14: 125.39145 | W14: 118.86031
A15: 1998.III | B15: 115.40525 | C15: 114.85611 | D15: 104.55575 | E15: 109.69225 | F15: 116.98459 | G15: 108.82533 | H15: 109.85022 | I15: 121.41198 | J15: 123.69368 | K15: 109.3969 | L15: 107.28706 | M15: 105.767 | N15: 108.07822 | O15: 109.02159 | P15: 109.30189 | Q15: 113.68091 | R15: 109.87785 | S15: 106.9313 | T15: 104.31882 | U15: 112.83769 | V15: 125.16962 | W15: 129.85047
A16: 1998.IV | B16: 78.267793 | C16: 115.10162 | D16: 96.582876 | E16: 111.00423 | F16: 109.77129 | G16: 102.15394 | H16: 102.63327 | I16: 116.06784 | J16: 136.5425 | K16: 114.48751 | L16: 109.25941 | M16: 108.41376 | N16: 107.92166 | O16: 110.14941 | P16: 106.37033 | Q16: 108.30732 | R16: 106.66197 | S16: 107.76311 | T16: 106.0713 | U16: 103.90613 | V16: 108.79039 | W16: 122.13963
... A123: 2025.III | B123: 272.1191 | C123: 281.3102 | D123: 125.93547 | E123: 210.12246 | F123: 163.91353 | G123: 152.97397 | H123: 178.11191 | I123: 182.33927 | J123: 470.58412 | K123: 245.46161 | L123: 239.84921 | M123: 208.01438 | N123: 162.78732 | O123: 207.67061 | P123: 195.28262 | Q123: 217.91566 | R123: 198.66041 | S123: 209.50518 | T123: 166.75133 | U123: 188.17996 | V123: 416.79616 | W123: 327.90317
A124: 2025.IV | B124: 172.1698 | C124: 278.6737 | D124: 116.12603 | E124: 216.65883 | F124: 156.38244 | G124: 145.24274 | H124: 172.63282 | I124: 175.35562 | J124: 503.41962 | K124: 262.00707 | L124: 239.17022 | M124: 213.16815 | N124: 161.20424 | O124: 209.08286 | P124: 188.94688 | Q124: 216.47439 | R124: 192.93911 | S124: 213.24282 | T124: 169.5635 | U124: 175.73702 | V124: 411.85074 | W124: 311.14289 | Y124: =R124/R120-1 -> 0.018433314
A125: 2026.I | B125: 379.77918 | C125: 270.31389 | D125: 109.65618 | E125: 223.3555 | F125: 155.82454 | G125: 139.95923 | H125: 163.61206 | I125: 165.90898 | J125: 470.96802 | K125: 246.32367 | L125: 238.02635 | M125: 200.39203 | N125: 160.32972 | O125: 200.91147 | P125: 191.83067 | Q125: 209.23279 | R125: 194.52822 | S125: 204.53967 | T125: 160.01096 | U125: 178.18293 | V125: 375.72087 | W125: 312.20785
A126: 2026.II | B126: 371.0928 | C126: 291.39842 | D126: 116.1282 | E126: 219.62928 | F126: 158.17182 | G126: 146.5345 | H126: 168.93313 | I126: 174.03293 | J126: 490.37098 | K126: 245.78656 | L126: 240.27204 | M126: 205.64921 | N126: 162.43431 | O126: 205.02835 | P126: 196.14415 | Q126: 215.10356 | R126: 199.05207 | S126: 204.86363 | T126: 168.48244 | U126: 180.75093 | V126: 416.30432 | W126: 324.60275

Sheet Valores Encadeados a Preços 95
A1: VALORES ENCADEADOS A PREÇOS DE 1995
A2: (1.000.000 R$)
A3: Período | B3: AGROPECUÁRIA | C3: INDÚSTRIA | H3: SERVIÇOS | P3: VA | Q3: Imposto | R3: PIB | S3: Consumo das Famílias | T3: Consumo do Governo | U3: Formação Bruta de Capital Fixo | V3: Exportação | W3: Importação | Y3: =SUM(O5:O8)/SUM(R5:R8) -> 0.58172751
B4: Total | C4: Indústrias extrativas | D4: Indústrias de transformação | E4: Eletricidade e gás, água, esgoto, ativ. de gestão de resíduos | F4: Construção | G4: Total | H4: Comércio | I4: Transporte, armazenagem e correio | J4: Informação e comunicação | K4: Atividades financeiras, de seguros e serviços relacionados | L4: Atividades Imobiliárias | M4: Outras atividades de serviços | N4: Adm., defesa, saúde e educação públicas e seguridade social | O4: Total
A5: 1996.I | B5: 9316.4023 | C5: 1106.9757 | D5: 22989.131 | E5: 3835.49 | F5: 10525.133 | G5: 38456.73 | H5: 12731.938 | I5: 5031.3911 | J5: 3740.8413 | K5: 15329.091 | L5: 15372.839 | M5: 22400.282 | N5: 26246.878 | O5: 100853.26 | P5: 148626.39 | Q5: 22293.605 | R5: 170920 | S5: 108013.04 | T5: 35503.235 | U5: 33266.712 | V5: 12645.247 | W5: 13696.725
A6: 1996.II | B6: 9332.3862 | C6: 1102.103 | D6: 24655.238 | E6: 3771.9319 | F6: 10872.623 | G6: 40401.895 | H6: 13999.034 | I6: 5344.7762 | J6: 3843.036 | K6: 14879.984 | L6: 15479.601 | M6: 22772.56 | N6: 26862.113 | O6: 103181.1 | P6: 152915.38 | Q6: 23793.361 | R6: 176708.75 | S6: 112161.27 | T6: 36962.559 | U6: 36227.638 | V6: 13904.323 | W6: 16388.472
A7: 1996.III | B7: 9561.6198 | C7: 1119.0546 | D7: 29570.694 | E7: 3816.5403 | F7: 11555.106 | G7: 46061.395 | H7: 15154.669 | I7: 5910.4544 | J7: 3985.847 | K7: 17653.075 | L7: 15500.332 | M7: 23450.119 | N7: 26829.583 | O7: 108484.08 | P7: 164107.09 | Q7: 25737.166 | R7: 189844.26 | S7: 117771.28 | T7: 38783.503 | U7: 37688.095 | V7: 14175.078 | W7: 19098.502 | AD7: Agropecuária | AE7: Indústria | AF7: Serviços | AG7: Impostos | AR7: Consumo das Famílias | AS7: Consumo do Governo | AT7: Formação Bruta de Capital Fixo | AU7: Variação de Estoques | AV7: Exportação | AW7: Importação | AY7: Consumo das Famílias | AZ7: Consumo do Governo | BA7: Formação Bruta de Capital Fixo | BB7: Variação de Estoques | BC7: Exportação | BD7: Importação
A8: 1996.IV | B8: 8216.4229 | C8: 1190.7277 | D8: 25534.559 | E8: 3980.5333 | F8: 11054.104 | G8: 41759.925 | H8: 14838.437 | I8: 5643.5879 | J8: 4146.6653 | K8: 17097.343 | L8: 15285.664 | M8: 23869.56 | N8: 26366.694 | O8: 107247.95 | P8: 157224.3 | Q8: 26888.643 | R8: 184112.94 | S8: 126373.4 | T8: 33802.566 | U8: 37749.323 | V8: 12205.403 | W8: 21306.453 | Y8: =SUM('Valores Correntes'!B5:B8)/SUM('Valores Correntes'!$R5:$R8) -> 0.047684112 | Z8: =SUM('Valores Correntes'!G5:G8)/SUM('Valores Correntes'!$R5:$R8) -> 0.22340115 | AA8: =SUM('Valores Correntes'!O5:O8)/SUM('Valores Correntes'!$R5:$R8) -> 0.6031888 | AB8: =SUM('Valores Correntes'!Q5:Q8)/SUM('Valores Correntes'!$R5:$R8) -> 0.12572594 | AD8: ='Acum. em 4 trimestres'!B8/100 -> 0.029531711 | AE8: ='Acum. em 4 trimestres'!G8/100 -> 0.0097461659 | AF8: ='Acum. em 4 trimestres'!O8/100 -> 0.022991377 | AG8: ='Acum. em 4 trimestres'!Q8/100 -> 0.036831528 | AH8: 1996.IV | AR8: =SUM('Valores Correntes'!S5:S8)/SUM('Valores Correntes'!$R5:$R8) -> 0.65157399 | AS8: =SUM('Valores Correntes'!T5:T8)/SUM('Valores Correntes'!$R5:$R8) -> 0.19750827 | AT8: =SUM('Valores Correntes'!U5:U8)/SUM('Valores Correntes'!$R5:$R8) -> 0.18640654 | AU8: =SUM('Valores Correntes'!V5:V8)/SUM('Valores Correntes'!$R5:$R8) -> -0.013737074 | AV8: =SUM('Valores Correntes'!W5:W8)/SUM('Valores Correntes'!$R5:$R8) -> 0.067302097 | AW8: =SUM('Valores Correntes'!X5:X8)/SUM('Valores Correntes'!$R5:$R8) -> 0.089053818 | AY8: ='Acum. em 4 trimestres'!S8/100 -> 0.032365808 | AZ8: ='Acum. em 4 trimestres'!T8/100 -> -0.018257396 | BA8: ='Acum. em 4 trimestres'!U8/100 -> 0.011955211 | BC8: ='Acum. em 4 trimestres'!V8/100 -> -0.0041986447 | BD8: ='Acum. em 4 trimestres'!W8/100 -> 0.055943152 | BF8: 1996.IV
A9: 1997.I | B9: 9966.1497 | C9: 1096.7676 | D9: 23619.05 | E9: 4053.5522 | F9: 10859.406 | G9: 39718.818 | H9: 13312.429 | I9: 5083.4999 | J9: 3915.4617 | K9: 15588.252 | L9: 15582.302 | M9: 22594.838 | N9: 26433.269 | O9: 102783.99 | P9: 152447.8 | Q9: 24295.421 | R9: 176732.25 | S9: 116539.91 | T9: 35940.992 | U9: 37012.819 | V9: 12583.747 | W9: 17469.31 | Y9: =SUM('Valores Correntes'!B6:B9)/SUM('Valores Correntes'!$R6:$R9) -> 0.048660331 | Z9: =SUM('Valores Correntes'!G6:G9)/SUM('Valores Correntes'!$R6:$R9) -> 0.22446671 | AA9: =SUM('Valores Correntes'!O6:O9)/SUM('Valores Correntes'!$R6:$R9) -> 0.60308442 | AB9: =SUM('Valores Correntes'!Q6:Q9)/SUM('Valores Correntes'!$R6:$R9) -> 0.12378853 | AD9: ='Acum. em 4 trimestres'!B9/100 -> 0.040956496 | AE9: ='Acum. em 4 trimestres'!G9/100 -> 0.032773883 | AF9: ='Acum. em 4 trimestres'!O9/100 -> 0.02105901 | AG9: ='Acum. em 4 trimestres'!Q9/100 -> 0.075512526 | AH9: 1997.I | AR9: =SUM('Valores Correntes'!S6:S9)/SUM('Valores Correntes'!$R6:$R9) -> 0.65463775 | AS9: =SUM('Valores Correntes'!T6:T9)/SUM('Valores Correntes'!$R6:$R9) -> 0.19817348 | AT9: =SUM('Valores Correntes'!U6:U9)/SUM('Valores Correntes'!$R6:$R9) -> 0.18837332 | AU9: =SUM('Valores Correntes'!V6:V9)/SUM('Valores Correntes'!$R6:$R9) -> -0.015977703 | AV9: =SUM('Valores Correntes'!W6:W9)/SUM('Valores Correntes'!$R6:$R9) -> 0.066003072 | AW9: =SUM('Valores Correntes'!X6:X9)/SUM('Valores Correntes'!$R6:$R9) -> 0.091209917 | AY9: ='Acum. em 4 trimestres'!S9/100 -> 0.054520213 | AZ9: ='Acum. em 4 trimestres'!T9/100 -> -0.0072613477 | BA9: ='Acum. em 4 trimestres'!U9/100 -> 0.074286228 | BC9: ='Acum. em 4 trimestres'!V9/100 -> -0.01589057 | BD9: ='Acum. em 4 trimestres'!W9/100 -> 0.15839967 | BF9: 1997.I
A10: 1997.II | B10: 9743.8087 | C10: 1142.2199 | D10: 26918.188 | E10: 3971.5179 | F10: 11614.172 | G10: 43647.677 | H10: 14757.726 | I10: 5789.6955 | J10: 4069.2723 | K10: 15051.693 | L10: 15695.693 | M10: 23288.4 | N10: 26703.072 | O10: 105502.23 | P10: 158774.9 | Q10: 26437.814 | R10: 185109.48 | S10: 118881.66 | T10: 36670.029 | U10: 40103.563 | V10: 15897.837 | W10: 20292.901 | Y10: =SUM('Valores Correntes'!B7:B10)/SUM('Valores Correntes'!$R7:$R10) -> 0.04816334 | Z10: =SUM('Valores Correntes'!G7:G10)/SUM('Valores Correntes'!$R7:$R10) -> 0.22824474 | AA10: =SUM('Valores Correntes'!O7:O10)/SUM('Valores Correntes'!$R7:$R10) -> 0.60120389 | AB10: =SUM('Valores Correntes'!Q7:Q10)/SUM('Valores Correntes'!$R7:$R10) -> 0.12238803 | AD10: ='Acum. em 4 trimestres'!B10/100 -> 0.046706724 | AE10: ='Acum. em 4 trimestres'!G10/100 -> 0.060831953 | AF10: ='Acum. em 4 trimestres'!O10/100 -> 0.017646255 | AG10: ='Acum. em 4 trimestres'!Q10/100 -> 0.10847858 | AH10: 1997.II | AR10: =SUM('Valores Correntes'!S7:S10)/SUM('Valores Correntes'!$R7:$R10) -> 0.65838791 | AS10: =SUM('Valores Correntes'!T7:T10)/SUM('Valores Correntes'!$R7:$R10) -> 0.19911324 | AT10: =SUM('Valores Correntes'!U7:U10)/SUM('Valores Correntes'!$R7:$R10) -> 0.19005642 | AU10: =SUM('Valores Correntes'!V7:V10)/SUM('Valores Correntes'!$R7:$R10) -> -0.020640274 | AV10: =SUM('Valores Correntes'!W7:W10)/SUM('Valores Correntes'!$R7:$R10) -> 0.067053604 | AW10: =SUM('Valores Correntes'!X7:X10)/SUM('Valores Correntes'!$R7:$R10) -> 0.093970904 | AY10: ='Acum. em 4 trimestres'!S10/100 -> 0.064732685 | AZ10: ='Acum. em 4 trimestres'!T10/100 -> -0.0086766885 | BA10: ='Acum. em 4 trimestres'!U10/100 -> 0.11467143 | BC10: ='Acum. em 4 trimestres'!V10/100 -> 0.009901604 | BD10: ='Acum. em 4 trimestres'!W10/100 -> 0.241773 | BF10: 1997.II
A11: 1997.III | B11: 9702.8717 | C11: 1244.42 | D11: 28202.175 | E11: 4075.2588 | F11: 12589.109 | G11: 46159.955 | H11: 15650.673 | I11: 6169.9939 | J11: 4092.8695 | K11: 17839.454 | L11: 15749.902 | M11: 24074.892 | N11: 26588.054 | O11: 109863.14 | P11: 165600.19 | Q11: 27768.059 | R11: 193244.9 | S11: 120195.36 | T11: 36566.731 | U11: 40895.752 | V11: 16655.432 | W11: 22132.607 | Y11: =SUM('Valores Correntes'!B8:B11)/SUM('Valores Correntes'!$R8:$R11) -> 0.046656504 | Z11: =SUM('Valores Correntes'!G8:G11)/SUM('Valores Correntes'!$R8:$R11) -> 0.23085654 | AA11: =SUM('Valores Correntes'!O8:O11)/SUM('Valores Correntes'!$R8:$R11) -> 0.60096564 | AB11: =SUM('Valores Correntes'!Q8:Q11)/SUM('Valores Correntes'!$R8:$R11) -> 0.12152131 | AD11: ='Acum. em 4 trimestres'!B11/100 -> 0.052349244 | AE11: ='Acum. em 4 trimestres'!G11/100 -> 0.031440225 | AF11: ='Acum. em 4 trimestres'!O11/100 -> 0.012758239 | AG11: ='Acum. em 4 trimestres'!Q11/100 -> 0.10285117 | AI11: Agropecuária | AJ11: Indústria | AK11: Serviços | AL11: Impostos | AM11: PIB | AR11: =SUM('Valores Correntes'!S8:S11)/SUM('Valores Correntes'!$R8:$R11) -> 0.65700144 | AS11: =SUM('Valores Correntes'!T8:T11)/SUM('Valores Correntes'!$R8:$R11) -> 0.1981621 | AT11: =SUM('Valores Correntes'!U8:U11)/SUM('Valores Correntes'!$R8:$R11) -> 0.19131698 | AU11: =SUM('Valores Correntes'!V8:V11)/SUM('Valores Correntes'!$R8:$R11) -> -0.018910851 | AV11: =SUM('Valores Correntes'!W8:W11)/SUM('Valores Correntes'!$R8:$R11) -> 0.06845543 | AW11: =SUM('Valores Correntes'!X8:X11)/SUM('Valores Correntes'!$R8:$R11) -> 0.096025102 | AY11: ='Acum. em 4 trimestres'!S11/100 -> 0.056004507 | AZ11: ='Acum. em 4 trimestres'!T11/100 -> -0.030717428 | BA11: ='Acum. em 4 trimestres'!U11/100 -> 0.11000093 | BC11: ='Acum. em 4 trimestres'!V11/100 -> 0.066092356 | BD11: ='Acum. em 4 trimestres'!W11/100 -> 0.24079648 | BG11: Consumo das Famílias | BH11: Consumo do Governo | BI11: Formação Bruta de Capital Fixo | BJ11: Variação de Estoques | BK11: Exportação | BL11: Importação | BM11: PIB
A12: 1997.IV | B12: 7310.1614 | C12: 1261.2964 | D12: 26572.174 | E12: 4213.7517 | F12: 12291.249 | G12: 44445.729 | H12: 15189.564 | I12: 6232.5641 | J12: 4462.1054 | K12: 18642.336 | L12: 16155.203 | M12: 25139.409 | N12: 26536.009 | O12: 112254.89 | P12: 164180.38 | Q12: 26885.802 | R12: 190996.04 | S12: 122784.74 | T12: 37682.084 | U12: 39120.157 | V12: 13625.549 | W12: 20883.425 | Y12: =SUM('Valores Correntes'!B9:B12)/SUM('Valores Correntes'!$R9:$R12) -> 0.04685047 | Z12: =SUM('Valores Correntes'!G9:G12)/SUM('Valores Correntes'!$R9:$R12) -> 0.22594148 | AA12: =SUM('Valores Correntes'!O9:O12)/SUM('Valores Correntes'!$R9:$R12) -> 0.60605713 | AB12: =SUM('Valores Correntes'!Q9:Q12)/SUM('Valores Correntes'!$R9:$R12) -> 0.12115093 | AD12: ='Acum. em 4 trimestres'!B12/100 -> 0.0081302798 | AE12: ='Acum. em 4 trimestres'!G12/100 -> 0.043749925 | AF12: ='Acum. em 4 trimestres'!O12/100 -> 0.025342338 | AG12: ='Acum. em 4 trimestres'!Q12/100 -> 0.067613546 | AH12: 1997.IV | AI12: =Y8*AD12 -> 0.00038768517 | AJ12: =Z8*AE12 -> 0.0097737833 | AK12: =AA8*AF12 -> 0.015286214 | AL12: =AB8*AG12 -> 0.008500777 | AM12: ='PIB Var. Real 4t'!Z11 -> 0.03394846 | AN12: =SUM(AI12:AL12)-('Acum. em 4 trimestres'!R12/100) -> -5.1347815e-16 | AR12: =SUM('Valores Correntes'!S9:S12)/SUM('Valores Correntes'!$R9:$R12) -> 0.6530963 | AS12: =SUM('Valores Correntes'!T9:T12)/SUM('Valores Correntes'!$R9:$R12) -> 0.19535295 | AT12: =SUM('Valores Correntes'!U9:U12)/SUM('Valores Correntes'!$R9:$R12) -> 0.19122901 | AU12: =SUM('Valores Correntes'!V9:V12)/SUM('Valores Correntes'!$R9:$R12) -> -0.013589155 | AV12: =SUM('Valores Correntes'!W9:W12)/SUM('Valores Correntes'!$R9:$R12) -> 0.069836496 | AW12: =SUM('Valores Correntes'!X9:X12)/SUM('Valores Correntes'!$R9:$R12) -> 0.095925597 | AY12: ='Acum. em 4 trimestres'!S12/100 -> 0.030329739 | AZ12: ='Acum. em 4 trimestres'!T12/100 -> 0.012464329 | BA12: ='Acum. em 4 trimestres'!U12/100 -> 0.084181144 | BC12: ='Acum. em 4 trimestres'!V12/100 -> 0.11019289 | BD12: ='Acum. em 4 trimestres'!W12/100 -> 0.14595077 | BF12: 1997.IV | BG12: =AY12*AR8 -> 0.019762069 | BH12: =AZ12*AS8 -> 0.0024618079 | BI12: =BA12*AT8 -> 0.015691916 | BJ12: =BB12*AU8 -> 0 | BK12: =BC12*AV8 -> 0.0074162124 | BL12: =BD12*AW8 -> 0.012997473 | BM12: =AM12 -> 0.03394846 | BO12: =BG12+BH12+BI12+BJ12+(BK12-BL12) -> 0.032334532 | BQ12: =BM12-BO12 -> 0.0016139282
A13: 1998.I | B13: 9825.1132 | C13: 1181.109 | D13: 22615.581 | E13: 4208.0052 | F13: 11530.069 | G13: 39744.847 | H13: 13379.063 | I13: 5226.2605 | J13: 4091.2864 | K13: 15263.859 | L13: 16041.396 | M13: 22824.179 | N13: 26836.515 | O13: 104221.16 | P13: 153828.68 | Q13: 24669.713 | R13: 178512.96 | S13: 115955.51 | T13: 36380.05 | U13: 38304.214 | V13: 13895.033 | W13: 18841.591 | Y13: =SUM('Valores Correntes'!B10:B13)/SUM('Valores Correntes'!$R10:$R13) -> 0.045564136 | Z13: =SUM('Valores Correntes'!G10:G13)/SUM('Valores Correntes'!$R10:$R13) -> 0.22556557 | AA13: =SUM('Valores Correntes'!O10:O13)/SUM('Valores Correntes'!$R10:$R13) -> 0.60745322 | AB13: =SUM('Valores Correntes'!Q10:Q13)/SUM('Valores Correntes'!$R10:$R13) -> 0.12141707 | AD13: ='Acum. em 4 trimestres'!B13/100 -> -0.013340594 | AE13: ='Acum. em 4 trimestres'!G13/100 -> 0.036061108 | AF13: ='Acum. em 4 trimestres'!O13/100 -> 0.024055865 | AG13: ='Acum. em 4 trimestres'!Q13/100 -> 0.050109891 | AH13: 1998.I | AI13: =Y9*AD13 -> -0.00064915774 | AJ13: =Z9*AE13 -> 0.0080945182 | AK13: =AA9*AF13 -> 0.014507718 | AL13: =AB9*AG13 -> 0.0062030299 | AM13: ='PIB Var. Real 4t'!Z12 -> 0.028134774 | AN13: =SUM(AI13:AL13)-('Acum. em 4 trimestres'!R13/100) -> 2.1333866e-05 | AR13: =SUM('Valores Correntes'!S10:S13)/SUM('Valores Correntes'!$R10:$R13) -> 0.65151087 | AS13: =SUM('Valores Correntes'!T10:T13)/SUM('Valores Correntes'!$R10:$R13) -> 0.19702054 | AT13: =SUM('Valores Correntes'!U10:U13)/SUM('Valores Correntes'!$R10:$R13) -> 0.19094704 | AU13: =SUM('Valores Correntes'!V10:V13)/SUM('Valores Correntes'!$R10:$R13) -> -0.014409728 | AV13: =SUM('Valores Correntes'!W10:W13)/SUM('Valores Correntes'!$R10:$R13) -> 0.071672729 | AW13: =SUM('Valores Correntes'!X10:X13)/SUM('Valores Correntes'!$R10:$R13) -> 0.096741457 | AY13: ='Acum. em 4 trimestres'!S13/100 -> 0.010513803 | AZ13: ='Acum. em 4 trimestres'!T13/100 -> 0.01243576 | BA13: ='Acum. em 4 trimestres'!U13/100 -> 0.065549843 | BC13: ='Acum. em 4 trimestres'!V13/100 -> 0.1362871 | BD13: ='Acum. em 4 trimestres'!W13/100 -> 0.10621462 | BF13: 1998.I | BG13: =AY13*AR9 -> 0.0068827321 | BH13: =AZ13*AS9 -> 0.0024644378 | BI13: =BA13*AT9 -> 0.012347841 | BJ13: =BB13*AU9 -> 0 | BK13: =BC13*AV9 -> 0.008995367 | BL13: =BD13*AW9 -> 0.0096878262 | BM13: =AM13 -> 0.028134774 | BO13: =BG13+BH13+BI13+BJ13+(BK13-BL13) -> 0.021002552 | BQ13: =BM13-BO13 -> 0.0071322222
A14: 1998.II | B14: 11018.403 | C14: 1199.1522 | D14: 25971.841 | E14: 4066.4498 | F14: 12173.067 | G14: 43524.839 | H14: 14833.758 | I14: 5881.4376 | J14: 4112.7975 | K14: 14820.652 | L14: 16174.754 | M14: 23778.494 | N14: 27466.65 | O14: 107468.87 | P14: 161855.13 | Q14: 26046.253 | R14: 187904 | S14: 117598.09 | T14: 37498.745 | U14: 40965.746 | V14: 16662.399 | W14: 19836.488 | Y14: =SUM('Valores Correntes'!B11:B14)/SUM('Valores Correntes'!$R11:$R14) -> 0.047294133 | Z14: =SUM('Valores Correntes'!G11:G14)/SUM('Valores Correntes'!$R11:$R14) -> 0.22399694 | AA14: =SUM('Valores Correntes'!O11:O14)/SUM('Valores Correntes'!$R11:$R14) -> 0.60740895 | AB14: =SUM('Valores Correntes'!Q11:Q14)/SUM('Valores Correntes'!$R11:$R14) -> 0.12129999 | AD14: ='Acum. em 4 trimestres'!B14/100 -> 0.0098311107 | AE14: ='Acum. em 4 trimestres'!G14/100 -> 0.015699458 | AF14: ='Acum. em 4 trimestres'!O14/100 -> 0.023088164 | AG14: ='Acum. em 4 trimestres'!Q14/100 -> 0.019454345 | AH14: 1998.II | AI14: =Y10*AD14 -> 0.00047349913 | AJ14: =Z10*AE14 -> 0.0035833186 | AK14: =AA10*AF14 -> 0.013880694 | AL14: =AB10*AG14 -> 0.0023809789 | AM14: ='PIB Var. Real 4t'!Z13 -> 0.020194318 | AN14: =SUM(AI14:AL14)-('Acum. em 4 trimestres'!R14/100) -> 0.00012417286 | AR14: =SUM('Valores Correntes'!S11:S14)/SUM('Valores Correntes'!$R11:$R14) -> 0.64375413 | AS14: =SUM('Valores Correntes'!T11:T14)/SUM('Valores Correntes'!$R11:$R14) -> 0.19709092 | AT14: =SUM('Valores Correntes'!U11:U14)/SUM('Valores Correntes'!$R11:$R14) -> 0.18948206 | AU14: =SUM('Valores Correntes'!V11:V14)/SUM('Valores Correntes'!$R11:$R14) -> -0.0068324245 | AV14: =SUM('Valores Correntes'!W11:W14)/SUM('Valores Correntes'!$R11:$R14) -> 0.071710927 | AW14: =SUM('Valores Correntes'!X11:X14)/SUM('Valores Correntes'!$R11:$R14) -> 0.095205612 | AY14: ='Acum. em 4 trimestres'!S14/100 -> -0.0063235191 | AZ14: ='Acum. em 4 trimestres'!T14/100 -> 0.020183044 | BA14: ='Acum. em 4 trimestres'!U14/100 -> 0.044129154 | BC14: ='Acum. em 4 trimestres'!V14/100 -> 0.10893407 | BD14: ='Acum. em 4 trimestres'!W14/100 -> 0.045120543 | BF14: 1998.II | BG14: =AY14*AR10 -> -0.0041633285 | BH14: =AZ14*AS10 -> 0.0040187112 | BI14: =BA14*AT10 -> 0.0083870292 | BJ14: =BB14*AU10 -> 0 | BK14: =BC14*AV10 -> 0.0073044222 | BL14: =BD14*AW10 -> 0.0042400182 | BM14: =AM14 -> 0.020194318 | BO14: =BG14+BH14+BI14+BJ14+(BK14-BL14) -> 0.011306816 | BQ14: =BM14-BO14 -> 0.0088875022
A15: 1998.III | B15: 10208.154 | C15: 1266.665 | D15: 26836.131 | E15: 4096.6822 | F15: 12591.561 | G15: 44909.8 | H15: 15300.428 | I15: 6302.4001 | J15: 4586.5226 | K15: 17610.823 | L15: 16147.228 | M15: 24463.461 | N15: 27535.704 | O15: 111837.7 | P15: 166899.99 | Q15: 27057.814 | R15: 193932.08 | S15: 120234.11 | T15: 38532.603 | U15: 40401.408 | V15: 16632.922 | W15: 21670.625 | Y15: =SUM('Valores Correntes'!B12:B15)/SUM('Valores Correntes'!$R12:$R15) -> 0.049005087 | Z15: =SUM('Valores Correntes'!G12:G15)/SUM('Valores Correntes'!$R12:$R15) -> 0.22236108 | AA15: =SUM('Valores Correntes'!O12:O15)/SUM('Valores Correntes'!$R12:$R15) -> 0.60830176 | AB15: =SUM('Valores Correntes'!Q12:Q15)/SUM('Valores Correntes'!$R12:$R15) -> 0.12033208 | AD15: ='Acum. em 4 trimestres'!B15/100 -> 0.019468343 | AE15: ='Acum. em 4 trimestres'!G15/100 -> 0.0078163842 | AF15: ='Acum. em 4 trimestres'!O15/100 -> 0.024413181 | AG15: ='Acum. em 4 trimestres'!Q15/100 -> -0.006930035 | AH15: 1998.III | AI15: =Y11*AD15 -> 0.00090832485 | AJ15: =Z11*AE15 -> 0.0018044634 | AK15: =AA11*AF15 -> 0.014671483 | AL15: =AB11*AG15 -> -0.00084214695 | AM15: ='PIB Var. Real 4t'!Z14 -> 0.016430603 | AN15: =SUM(AI15:AL15)-('Acum. em 4 trimestres'!R15/100) -> 0.00011152132 | AR15: =SUM('Valores Correntes'!S12:S15)/SUM('Valores Correntes'!$R12:$R15) -> 0.64196487 | AS15: =SUM('Valores Correntes'!T12:T15)/SUM('Valores Correntes'!$R12:$R15) -> 0.1987625 | AT15: =SUM('Valores Correntes'!U12:U15)/SUM('Valores Correntes'!$R12:$R15) -> 0.187582 | AU15: =SUM('Valores Correntes'!V12:V15)/SUM('Valores Correntes'!$R12:$R15) -> -0.0051558441 | AV15: =SUM('Valores Correntes'!W12:W15)/SUM('Valores Correntes'!$R12:$R15) -> 0.071117074 | AW15: =SUM('Valores Correntes'!X12:X15)/SUM('Valores Correntes'!$R12:$R15) -> 0.094270597 | AY15: ='Acum. em 4 trimestres'!S15/100 -> -0.011240628 | AZ15: ='Acum. em 4 trimestres'!T15/100 -> 0.049749242 | BA15: ='Acum. em 4 trimestres'!U15/100 -> 0.01945327 | BC15: ='Acum. em 4 trimestres'!V15/100 -> 0.060574425 | BD15: ='Acum. em 4 trimestres'!W15/100 -> 0.00038000926 | BF15: 1998.III | BG15: =AY15*AR11 -> -0.0073851089 | BH15: =AZ15*AS11 -> 0.0098584143 | BI15: =BA15*AT11 -> 0.0037217408 | BJ15: =BB15*AU11 -> 0 | BK15: =BC15*AV11 -> 0.0041466484 | BL15: =BD15*AW11 -> 3.6490428e-05 | BM15: =AM15 -> 0.016430603 | BO15: =BG15+BH15+BI15+BJ15+(BK15-BL15) -> 0.010305204 | BQ15: =BM15-BO15 -> 0.0061253988
A16: 1998.IV | B16: 6923.1663 | C16: 1269.3725 | D16: 24789.749 | E16: 4145.6811 | F16: 11815.161 | G16: 42156.667 | H16: 14295.218 | I16: 6024.9902 | J16: 5062.9527 | K16: 18430.315 | L16: 16444.076 | M16: 25075.645 | N16: 27495.816 | O16: 112994.65 | P16: 162423.61 | Q16: 25778.817 | R16: 188256.13 | S16: 121169.4 | T16: 39179.921 | U16: 37203.474 | V16: 14456.399 | W16: 20383.769 | Y16: =SUM('Valores Correntes'!B13:B16)/SUM('Valores Correntes'!$R13:$R16) -> 0.047500448 | Z16: =SUM('Valores Correntes'!G13:G16)/SUM('Valores Correntes'!$R13:$R16) -> 0.2211879 | AA16: =SUM('Valores Correntes'!O13:O16)/SUM('Valores Correntes'!$R13:$R16) -> 0.61118593 | AB16: =SUM('Valores Correntes'!Q13:Q16)/SUM('Valores Correntes'!$R13:$R16) -> 0.12012572 | AD16: ='Acum. em 4 trimestres'!B16/100 -> 0.034088881 | AE16: ='Acum. em 4 trimestres'!G16/100 -> -0.020900044 | AF16: ='Acum. em 4 trimestres'!O16/100 -> 0.014214815 | AG16: ='Acum. em 4 trimestres'!Q16/100 -> -0.01740725 | AH16: 1998.IV | AI16: =Y12*AD16 -> 0.0015970801 | AJ16: =Z12*AE16 -> -0.0047221867 | AK16: =AA12*AF16 -> 0.0086149901 | AL16: =AB12*AG16 -> -0.0021089045 | AM16: ='PIB Var. Real 4t'!Z15 -> 0.003380979 | AN16: =SUM(AI16:AL16)-('Acum. em 4 trimestres'!R16/100) -> -1.2915016e-15 | AR16: =SUM('Valores Correntes'!S13:S16)/SUM('Valores Correntes'!$R13:$R16) -> 0.64142301 | AS16: =SUM('Valores Correntes'!T13:T16)/SUM('Valores Correntes'!$R13:$R16) -> 0.20070532 | AT16: =SUM('Valores Correntes'!U13:U16)/SUM('Valores Correntes'!$R13:$R16) -> 0.18542348 | AU16: =SUM('Valores Correntes'!V13:V16)/SUM('Valores Correntes'!$R13:$R16) -> -0.0037759658 | AV16: =SUM('Valores Correntes'!W13:W16)/SUM('Valores Correntes'!$R13:$R16) -> 0.070305003 | AW16: =SUM('Valores Correntes'!X13:X16)/SUM('Valores Correntes'!$R13:$R16) -> 0.094080846 | AY16: ='Acum. em 4 trimestres'!S16/100 -> -0.0072001366 | AZ16: ='Acum. em 4 trimestres'!T16/100 -> 0.032217667 | BA16: ='Acum. em 4 trimestres'!U16/100 -> -0.0016384079 | BC16: ='Acum. em 4 trimestres'!V16/100 -> 0.049082053 | BD16: ='Acum. em 4 trimestres'!W16/100 -> -0.00056661237 | BF16: 1998.IV | BG16: =AY16*AR12 -> -0.0047023825 | BH16: =AZ16*AS12 -> 0.0062938163 | BI16: =BA16*AT12 -> -0.00031331112 | BJ16: =BB16*AU12 -> 0 | BK16: =BC16*AV12 -> 0.0034277186 | BL16: =BD16*AW12 -> -5.4352629e-05 | BM16: =AM16 -> 0.003380979 | BO16: =BG16+BH16+BI16+BJ16+(BK16-BL16) -> 0.0047601939 | BQ16: =BM16-BO16 -> -0.0013792148
A17: 1999.I | B17: 11061.007 | C17: 1167.804 | D17: 21655.491 | E17: 4124.4348 | F17: 10867.88 | G17: 38061.319 | H17: 13037.906 | I17: 5120.4203 | J17: 4857.3821 | K17: 15364.321 | L17: 16643.625 | M17: 23192.892 | N17: 27900.504 | O17: 107102.53 | P17: 156302.16 | Q17: 23339.434 | R17: 179883.35 | S17: 114869.73 | T17: 36637.386 | U17: 35087.199 | V17: 13881.699 | W17: 15475.855 | Y17: =SUM('Valores Correntes'!B14:B17)/SUM('Valores Correntes'!$R14:$R17) -> 0.04908342 | Z17: =SUM('Valores Correntes'!G14:G17)/SUM('Valores Correntes'!$R14:$R17) -> 0.21650772 | AA17: =SUM('Valores Correntes'!O14:O17)/SUM('Valores Correntes'!$R14:$R17) -> 0.61140269 | AB17: =SUM('Valores Correntes'!Q14:Q17)/SUM('Valores Correntes'!$R14:$R17) -> 0.12300617 | AD17: ='Acum. em 4 trimestres'!B17/100 -> 0.07185991 | AE17: ='Acum. em 4 trimestres'!G17/100 -> -0.030722058 | AF17: ='Acum. em 4 trimestres'!O17/100 -> 0.017511825 | AG17: ='Acum. em 4 trimestres'!Q17/100 -> -0.033462784 | AH17: 1999.I | AI17: =Y13*AD17 -> 0.0032742347 | AJ17: =Z13*AE17 -> -0.0069298387 | AK17: =AA13*AF17 -> 0.010637614 | AL17: =AB13*AG17 -> -0.0040629531 | AM17: ='PIB Var. Real 4t'!Z16 -> 0.0028242671 | AN17: =SUM(AI17:AL17)-('Acum. em 4 trimestres'!R17/100) -> 9.4790171e-05 | AR17: =SUM('Valores Correntes'!S14:S17)/SUM('Valores Correntes'!$R14:$R17) -> 0.63964323 | AS17: =SUM('Valores Correntes'!T14:T17)/SUM('Valores Correntes'!$R14:$R17) -> 0.19958968 | AT17: =SUM('Valores Correntes'!U14:U17)/SUM('Valores Correntes'!$R14:$R17) -> 0.18124635 | AU17: =SUM('Valores Correntes'!V14:V17)/SUM('Valores Correntes'!$R14:$R17) -> 0.0010573911 | AV17: =SUM('Valores Correntes'!W14:W17)/SUM('Valores Correntes'!$R14:$R17) -> 0.075222091 | AW17: =SUM('Valores Correntes'!X14:X17)/SUM('Valores Correntes'!$R14:$R17) -> 0.096758734 | AY17: ='Acum. em 4 trimestres'!S17/100 -> -0.0082582616 | AZ17: ='Acum. em 4 trimestres'!T17/100 -> 0.030887941 | BA17: ='Acum. em 4 trimestres'!U17/100 -> -0.030082991 | BC17: ='Acum. em 4 trimestres'!V17/100 -> 0.025960841 | BD17: ='Acum. em 4 trimestres'!W17/100 -> -0.058231976 | BF17: 1999.I | BG17: =AY17*AR13 -> -0.0053803473 | BH17: =AZ17*AS13 -> 0.0060855586 | BI17: =BA17*AT13 -> -0.0057442583 | BJ17: =BB17*AU13 -> 0 | BK17: =BC17*AV13 -> 0.0018606843 | BL17: =BD17*AW13 -> -0.0056334461 | BM17: =AM17 -> 0.0028242671 | BO17: =BG17+BH17+BI17+BJ17+(BK17-BL17) -> 0.0024550835 | BQ17: =BM17-BO17 -> 0.00036918366
A18: 1999.II | B18: 11194.744 | C18: 1109.3487 | D18: 24910.747 | E18: 4118.3669 | F18: 11368.521 | G18: 41602.135 | H18: 14231.842 | I18: 5383.5467 | J18: 5024.4155 | K18: 14891.081 | L18: 16594.85 | M18: 23879.711 | N18: 28442.611 | O18: 109264.09 | P18: 162013.95 | Q18: 24991.636 | R18: 187150.99 | S18: 116884.01 | T18: 37869.879 | U18: 36705.129 | V18: 16493.774 | W18: 16867.62 | Y18: =SUM('Valores Correntes'!B15:B18)/SUM('Valores Correntes'!$R15:$R18) -> 0.04759643 | Z18: =SUM('Valores Correntes'!G15:G18)/SUM('Valores Correntes'!$R15:$R18) -> 0.21695603 | AA18: =SUM('Valores Correntes'!O15:O18)/SUM('Valores Correntes'!$R15:$R18) -> 0.60973322 | AB18: =SUM('Valores Correntes'!Q15:Q18)/SUM('Valores Correntes'!$R15:$R18) -> 0.12571432 | AD18: ='Acum. em 4 trimestres'!B18/100 -> 0.040429506 | AE18: ='Acum. em 4 trimestres'!G18/100 -> -0.041095232 | AF18: ='Acum. em 4 trimestres'!O18/100 -> 0.017037281 | AG18: ='Acum. em 4 trimestres'!Q18/100 -> -0.039879788 | AH18: 1999.II | AI18: =Y14*AD18 -> 0.0019120784 | AJ18: =Z14*AE18 -> -0.009205206 | AK18: =AA14*AF18 -> 0.010348597 | AL18: =AB14*AG18 -> -0.0048374177 | AM18: ='PIB Var. Real 4t'!Z17 -> -0.0019121231 | AN18: =SUM(AI18:AL18)-('Acum. em 4 trimestres'!R18/100) -> 0.00013017495 | AR18: =SUM('Valores Correntes'!S15:S18)/SUM('Valores Correntes'!$R15:$R18) -> 0.63996173 | AS18: =SUM('Valores Correntes'!T15:T18)/SUM('Valores Correntes'!$R15:$R18) -> 0.1987138 | AT18: =SUM('Valores Correntes'!U15:U18)/SUM('Valores Correntes'!$R15:$R18) -> 0.17712011 | AU18: =SUM('Valores Correntes'!V15:V18)/SUM('Valores Correntes'!$R15:$R18) -> 0.0055675129 | AV18: =SUM('Valores Correntes'!W15:W18)/SUM('Valores Correntes'!$R15:$R18) -> 0.079729869 | AW18: =SUM('Valores Correntes'!X15:X18)/SUM('Valores Correntes'!$R15:$R18) -> 0.10109303 | AY18: ='Acum. em 4 trimestres'!S18/100 -> -0.0070854408 | AZ18: ='Acum. em 4 trimestres'!T18/100 -> 0.027626034 | BA18: ='Acum. em 4 trimestres'!U18/100 -> -0.062081203 | BC18: ='Acum. em 4 trimestres'!V18/100 -> 0.010295821 | BD18: ='Acum. em 4 trimestres'!W18/100 -> -0.089311727 | BF18: 1999.II | BG18: =AY18*AR14 -> -0.0045612818 | BH18: =AZ18*AS14 -> 0.0054448402 | BI18: =BA18*AT14 -> -0.011763274 | BJ18: =BB18*AU14 -> 0 | BK18: =BC18*AV14 -> 0.00073832283 | BL18: =BD18*AW14 -> -0.0085029777 | BM18: =AM18 -> -0.0019121231 | BO18: =BG18+BH18+BI18+BJ18+(BK18-BL18) -> -0.0016384154 | BQ18: =BM18-BO18 -> -0.00027370779
