Workbook

Sheet Outros Indicadores
A1: Coluna1 | B1: Selic | C1: IPCA | D1: Dólar | E1: Ibov | F1: Ibov/Dólar | G1: Resultado Primário | H1: Dívida Líquida | I1: Dívida Bruta | J1: Investimento Estrangeiro Direto | K1: Endividamento das Famílias (exc. Crédito Habitacional) | L1: IPOs B3 | M1: Índice de Confiança Empresarial | N1: Índice de Confiança do Consumidor | O1: Índice de Incerteza da Economia
A2: 34700 | B2: 0.4625 | C2: 6.3154 | D2: 0.8461 | E2: 3885 | F2: 4619.5006 | G2: 0.041
A3: 34731 | B3: 0.5654 | C3: 4.2683 | D3: 0.8398 | E3: 3270.9 | F3: 3845.8554 | G3: 0.0317
A4: 34759 | B4: 0.5798 | C4: 2.7478 | D4: 0.8884 | E4: 2979 | F4: 3328.4916 | G4: 0.0329
A5: 34790 | B5: 0.8547 | C5: 1.6905 | D5: 0.9065 | E5: 3813.7 | F5: 4181.6886 | G5: 0.0334
A6: 34820 | B6: 0.6105 | C6: 0.9179 | D6: 0.8964 | E6: 3720.6 | F6: 4111.1602 | G6: 0.0341
A7: 34851 | B7: 0.6084 | C7: 0.3303 | D7: 0.913 | E7: 3603.4 | F7: 3912.4864 | G7: 0.0281
A8: 34881 | B8: 0.6053 | C8: 0.2745 | D8: 0.9278 | E8: 3877.5 | F8: 4147.0588 | G8: 0.0249
A9: 34912 | B9: 0.5111 | C9: 0.2636 | D9: 0.941 | E9: 4310.5 | F9: 4537.3684 | G9: 0.0206
A10: 34943 | B10: 0.51 | C10: 0.2569 | D10: 0.9518 | E10: 4670.1 | F10: 4900.4197 | G10: 0.0164
A11: 34973 | B11: 0.4411 | C11: 0.2421 | D11: 0.9592 | E11: 4128.4 | F11: 4294.1544 | G11: 0.0118
A12: 35004 | B12: 0.4293 | C12: 0.2259 | D12: 0.9629 | E12: 4378.6 | F12: 4532.243 | G12: 0.0087
A13: 35034 | B13: 0.4122 | C13: 0.2241 | D13: 0.9678 | E13: 4299 | F13: 4422.8395 | G13: 0.0031 | J13: 4383.422
A14: 35065 | B14: 0.3383 | C14: 0.2197 | D14: 0.974 | E14: 5151.5 | F14: 5266.8439 | G14: -0.0019 | J14: 4654.22
A15: 35096 | B15: 0.3611 | C15: 0.2199 | D15: 0.9806 | E15: 4957.7 | F15: 5039.8495 | G15: 0.0009 | J15: 4870.237
A16: 35125 | B16: 0.3016 | C16: 0.2055 | D16: 0.9857 | E16: 4954.9 | F16: 5017.1122 | G16: 0.0012 | J16: 5488.542
A17: 35156 | B17: 0.2942 | C17: 0.1917 | D17: 0.9898 | E17: 5164.1 | F17: 5205.2212 | G17: -0.0038 | J17: 5920.877
A18: 35186 | B18: 0.2564 | C18: 0.1749 | D18: 0.9949 | E18: 5728 | F18: 5739.479 | G18: -0.0064 | J18: 7213.884
A19: 35217 | B19: 0.2965 | C19: 0.1626 | D19: 1.0009 | E19: 6043.9 | F19: 6019.8207 | G19: -0.0062 | J19: 8211.129
A20: 35247 | B20: 0.2328 | C20: 0.1484 | D20: 1.0065 | E20: 6123.3 | F20: 6057.875 | G20: -0.0057 | J20: 8445.443
A21: 35278 | B21: 0.2501 | C21: 0.1421 | D21: 1.013 | E21: 6259.4 | F21: 6157.7964 | G21: -0.0063 | J21: 8480.86
A22: 35309 | B22: 0.254 | C22: 0.1326 | D22: 1.0189 | E22: 6446.9 | F22: 6313.6813 | G22: -0.0059 | J22: 8224.787
A23: 35339 | B23: 0.2348 | C23: 0.1202 | D23: 1.0247 | E23: 6533.2 | F23: 6360.2025 | G23: -0.0071 | J23: 8808.858
A24: 35370 | B24: 0.2527 | C24: 0.1075 | D24: 1.03 | E24: 6666.1 | F24: 6454.3958 | G24: -0.0053 | J24: 9491.218
... A61: 36495 | B61: 0.1899 | C61: 0.0894 | D61: 1.8424 | E61: 17092 | F61: 9556.0774 | G61: 0.0227 | J61: 28385.676
A62: 36526 | B62: 0.1894 | C62: 0.0885 | D62: 1.8033 | E62: 16388 | F62: 9094.3396 | G62: 0.0233 | J62: 30112.053 | O62: 85.8
A63: 36557 | B63: 0.1887 | C63: 0.0786 | D63: 1.7749 | E63: 17660 | F63: 9988.1228 | G63: 0.0243 | J63: 27185.574 | O63: 86.1
A64: 36586 | B64: 0.1885 | C64: 0.0692 | D64: 1.7416 | E64: 17820 | F64: 10200.927 | G64: 0.0255 | J64: 27734.572 | O64: 85
A65: 36617 | B65: 0.1862 | C65: 0.0677 | D65: 1.7678 | E65: 15538 | F65: 8602.1148 | G65: 0.026 | J65: 26948.493 | O65: 86.3
A66: 36647 | B66: 0.1851 | C66: 0.0647 | D66: 1.8275 | E66: 14957 | F66: 8190.2311 | G66: 0.0288 | J66: 27358.284 | O66: 85.1
A67: 36678 | B67: 0.1804 | C67: 0.0651 | D67: 1.8079 | E67: 16728 | F67: 9295.399 | G67: 0.0269 | J67: 28735.192 | O67: 88.2
A68: 36708 | B68: 0.1685 | C68: 0.0706 | D68: 1.7974 | E68: 16455 | F68: 9273.5573 | G68: 0.024 | J68: 30308.683 | O68: 85.8
A69: 36739 | B69: 0.1652 | C69: 0.0786 | D69: 1.8088 | E69: 17347 | F69: 9515.6336 | G69: 0.0253 | J69: 30121.646 | O69: 86.5
A70: 36770 | B70: 0.1656 | C70: 0.0777 | D70: 1.8388 | E70: 15928 | F70: 8641.0242 | G70: 0.0233 | J70: 29181.28 | O70: 86.6
A71: 36800 | B71: 0.166 | C71: 0.0665 | D71: 1.8792 | E71: 14867 | F71: 7789.4792 | G71: 0.0216 | J71: 29183.63 | O71: 85.8
A72: 36831 | B72: 0.1651 | C72: 0.0599 | D72: 1.9476 | E72: 13287 | F72: 6781.8497 | G72: 0.0235 | J72: 33100.586 | O72: 86
A73: 36861 | B73: 0.1619 | C73: 0.0597 | D73: 1.9629 | E73: 15259 | F73: 7805.1151 | G73: 0.022 | J73: 32994.719 | O73: 83.6
A74: 36892 | B74: 0.1549 | C74: 0.0592 | D74: 1.9541 | E74: 17673 | F74: 8967.8794 | G74: 0.0229 | J74: 31632.649 | M74: 104.3 | O74: 88.1
A75: 36923 | B75: 0.152 | C75: 0.0627 | D75: 2.0015 | E75: 15891 | F75: 7771.4202 | G75: 0.022 | J75: 30936.254 | M75: 103.9 | O75: 86.2
A76: 36951 | B76: 0.1539 | C76: 0.0644 | D76: 2.0886 | E76: 14438 | F76: 6680.5478 | G76: 0.0214 | J76: 30783.336 | M76: 103.6 | O76: 86.6
...

Sheet Presidentes
A1: Coluna1 | B1: FHC I | C1: FHC II | D1: Lula I | E1: Lula II | F1: Dilma I | G1: Dilma II | H1: Temer | I1: Bolsonaro | J1: Lula III
A2: 34700 | B2: 100
A3: 34731 | B3: 100
A4: 34759 | B4: 100
A5: 34790 | B5: 100
A6: 34820 | B6: 100
A7: 34851 | B7: 100
A8: 34881 | B8: 100
A9: 34912 | B9: 100
A10: 34943 | B10: 100
A11: 34973 | B11: 100
A12: 35004 | B12: 100
A13: 35034 | B13: 100
... A49: 36130 | B49: 100
A50: 36161 | C50: 100
A51: 36192 | C51: 100
A52: 36220 | C52: 100
A53: 36251 | C53: 100
A54: 36281 | C54: 100
A55: 36312 | C55: 100
A56: 36342 | C56: 100
A57: 36373 | C57: 100
A58: 36404 | C58: 100
A59: 36434 | C59: 100
A60: 36465 | C60: 100
A61: 36495 | C61: 100
... A97: 37591 | C97: 100
A98: 37622 | D98: 100
A99: 37653 | D99: 100
A100: 37681 | D100: 100
A101: 37712 | D101: 100
A102: 37742 | D102: 100
A103: 37773 | D103: 100
A104: 37803 | D104: 100
A105: 37834 | D105: 100
A106: 37865 | D106: 100
A107: 37895 | D107: 100
A108: 37926 | D108: 100
A109: 37956 | D109: 100
... A145: 39052 | D145: 100
...

Sheet Dívida Bruta
A1: Data | B1: 4468 - Dívida Líquida do Setor Público - Saldos em R$ milhões - Total - Governo Federal e Banco Central - R$ (milhões) | C1: 4501 - Divida líquida do governo geral - Saldos em R$ milhões - R$ (milhões) | D1: 4502 - Dívida bruta do governo geral - Saldos em R$ milhões - Metodologia utilizada até 2007 - R$ (milhões) | O1: Coluna1 | P1: FHC I | Q1: FHC II | R1: Lula I | S1: Lula II | T1: Dilma I | U1: Dilma II | V1: Temer | W1: Bolsonaro | X1: Lula III | AA1: FHC II | AB1: Lula I | AC1: Lula II | AD1: Dilma I | AE1: Dilma II | AF1: Temer | AG1: Bolsonaro | AH1: Lula III | AJ1: Data | AK1: 4382 - PIB acumulado dos últimos 12 meses - Valores correntes (R$ milhões) - R$ (milhões) | AN1: FHC II | AO1: Lula I | AP1: Lula II | AQ1: Dilma I | AR1: Dilma II | AS1: Temer | AT1: Bolsonaro | AU1: Lula III
A2: 33239 | B2: 4.63 | C2: - | D2: - | E2: =A2 -> 33239 | I2: =A2 -> 33239 | O2: 34700 | P2: {=IF(OR($O2<P$387,$O2>P$388),"",IFERROR(IF($O2=P$387,100,P1)*INDEX($B$2:$B$428,MATCH($O2,$A$2:$A$428,0))/INDEX($B$2:$B$428,MATCH($O2,$A$2:$A$428,0)-1),""))} -> 99.14702 | Q2: {=IF(OR($O2<Q$387,$O2>Q$388),"",IFERROR(IF($O2=Q$387,100,Q1)*INDEX($B$2:$B$428,MATCH($O2,$A$2:$A$428,0))/INDEX($B$2:$B$428,MATCH($O2,$A$2:$A$428,0)-1),""))} | R2: {=IF(OR($O2<R$387,$O2>R$388),"",IFERROR(IF($O2=R$387,100,R1)*INDEX($B$2:$B$428,MATCH($O2,$A$2:$A$428,0))/INDEX($B$2:$B$428,MATCH($O2,$A$2:$A$428,0)-1),""))} | S2: {=IF(OR($O2<S$387,$O2>S$388),"",IFERROR(IF($O2=S$387,100,S1)*INDEX($B$2:$B$428,MATCH($O2,$A$2:$A$428,0))/INDEX($B$2:$B$428,MATCH($O2,$A$2:$A$428,0)-1),""))} | T2: {=IF(OR($O2<T$387,$O2>T$388),"",IFERROR(IF($O2=T$387,100,T1)*INDEX($B$2:$B$428,MATCH($O2,$A$2:$A$428,0))/INDEX($B$2:$B$428,MATCH($O2,$A$2:$A$428,0)-1),""))} | U2: {=IF(OR($O2<U$387,$O2>U$388),"",IFERROR(IF($O2=U$387,100,U1)*INDEX($B$2:$B$428,MATCH($O2,$A$2:$A$428,0))/INDEX($B$2:$B$428,MATCH($O2,$A$2:$A$428,0)-1),""))} | V2: {=IF(OR($O2<V$387,$O2>V$388),"",IFERROR(IF($O2=V$387,100,V1)*INDEX($B$2:$B$428,MATCH($O2,$A$2:$A$428,0))/INDEX($B$2:$B$428,MATCH($O2,$A$2:$A$428,0)-1),""))} | W2: {=IF(OR($O2<W$387,$O2>W$388),"",IFERROR(IF($O2=W$387,100,W1)*INDEX($B$2:$B$428,MATCH($O2,$A$2:$A$428,0))/INDEX($B$2:$B$428,MATCH($O2,$A$2:$A$428,0)-1),""))} | X2: {=IF(OR($O2<X$387,$O2>X$388),"",IFERROR(IF($O2=X$387,100,X1)*INDEX($B$2:$B$428,MATCH($O2,$A$2:$A$428,0))/INDEX($B$2:$B$428,MATCH($O2,$A$2:$A$428,0)-1),""))} | AA2: {=IF(EDATE(AA$387,ROW()-2)>AA$388,"",IFERROR(IF(ROW()=2,100,AA1)*INDEX($D$2:$D$428,MATCH(EDATE(AA$387,ROW()-2),$A$2:$A$428,0))/INDEX($D$2:$D$428,MATCH(EDATE(AA$387,ROW()-2),$A$2:$A$428,0)-1),""))} -> 114.80601 | AB2: {=IF(EDATE(AB$387,ROW()-2)>AB$388,"",IFERROR(IF(ROW()=2,100,AB1)*INDEX($D$2:$D$428,MATCH(EDATE(AB$387,ROW()-2),$A$2:$A$428,0))/INDEX($D$2:$D$428,MATCH(EDATE(AB$387,ROW()-2),$A$2:$A$428,0)-1),""))} -> 102.67157 | AC2: {=IF(EDATE(AC$387,ROW()-2)>AC$388,"",IFERROR(IF(ROW()=2,100,AC1)*INDEX($D$2:$D$428,MATCH(EDATE(AC$387,ROW()-2),$A$2:$A$428,0))/INDEX($D$2:$D$428,MATCH(EDATE(AC$387,ROW()-2),$A$2:$A$428,0)-1),""))} -> 99.503129 | AD2: {=IF(EDATE(AD$387,ROW()-2)>AD$388,"",IFERROR(IF(ROW()=2,100,AD1)*INDEX($D$2:$D$428,MATCH(EDATE(AD$387,ROW()-2),$A$2:$A$428,0))/INDEX($D$2:$D$428,MATCH(EDATE(AD$387,ROW()-2),$A$2:$A$428,0)-1),""))} -> 96.984263 | AE2: {=IF(EDATE(AE$387,ROW()-2)>AE$388,"",IFERROR(IF(ROW()=2,100,AE1)*INDEX($D$2:$D$428,MATCH(EDATE(AE$387,ROW()-2),$A$2:$A$428,0))/INDEX($D$2:$D$428,MATCH(EDATE(AE$387,ROW()-2),$A$2:$A$428,0)-1),""))} -> 97.248539 | AF2: {=IF(EDATE(AF$387,ROW()-2)>AF$388,"",IFERROR(IF(ROW()=2,100,AF1)*INDEX($D$2:$D$428,MATCH(EDATE(AF$387,ROW()-2),$A$2:$A$428,0))/INDEX($D$2:$D$428,MATCH(EDATE(AF$387,ROW()-2),$A$2:$A$428,0)-1),""))} -> 102.21457 | AG2: {=IF(EDATE(AG$387,ROW()-2)>AG$388,"",IFERROR(IF(ROW()=2,100,AG1)*INDEX($D$2:$D$428,MATCH(EDATE(AG$387,ROW()-2),$A$2:$A$428,0))/INDEX($D$2:$D$428,MATCH(EDATE(AG$387,ROW()-2),$A$2:$A$428,0)-1),""))} -> 98.675768 | AH2: {=IF(EDATE(AH$387,ROW()-2)>AH$388,"",IFERROR(IF(ROW()=2,100,AH1)*INDEX($D$2:$D$428,MATCH(EDATE(AH$387,ROW()-2),$A$2:$A$428,0))/INDEX($D$2:$D$428,MATCH(EDATE(AH$387,ROW()-2),$A$2:$A$428,0)-1),""))} -> 97.727671 | AJ2: 32874 | AK2: 0.7 | AN2: =IF(EDATE(AN$387,ROW()-2)>AN$388,"",IFERROR((INDEX($AL$2:$AL$441,MATCH(EDATE(AN$387,ROW()-2),$AJ$2:$AJ$441,0))-INDEX($AL$2:$AL$441,MATCH(EDATE(AN$387,-1),$AJ$2:$AJ$441,0)))*100,"")) -> 7.3990042 | AO2: =IF(EDATE(AO$387,ROW()-2)>AO$388,"",IFERROR((INDEX($AL$2:$AL$441,MATCH(EDATE(AO$387,ROW()-2),$AJ$2:$AJ$441,0))-INDEX($AL$2:$AL$441,MATCH(EDATE(AO$387,-1),$AJ$2:$AJ$441,0)))*100,"")) -> 1.3391611 | AP2: =IF(EDATE(AP$387,ROW()-2)>AP$388,"",IFERROR((INDEX($AL$2:$AL$441,MATCH(EDATE(AP$387,ROW()-2),$AJ$2:$AJ$441,0))-INDEX($AL$2:$AL$441,MATCH(EDATE(AP$387,-1),$AJ$2:$AJ$441,0)))*100,"")) -> -0.9798724 | AQ2: =IF(EDATE(AQ$387,ROW()-2)>AQ$388,"",IFERROR((INDEX($AL$2:$AL$441,MATCH(EDATE(AQ$387,ROW()-2),$AJ$2:$AJ$441,0))-INDEX($AL$2:$AL$441,MATCH(EDATE(AQ$387,-1),$AJ$2:$AJ$441,0)))*100,"")) -> -2.5486449 | AR2: =IF(EDATE(AR$387,ROW()-2)>AR$388,"",IFERROR((INDEX($AL$2:$AL$441,MATCH(EDATE(AR$387,ROW()-2),$AJ$2:$AJ$441,0))-INDEX($AL$2:$AL$441,MATCH(EDATE(AR$387,-1),$AJ$2:$AJ$441,0)))*100,"")) -> -1.9098736 | AS2: =IF(EDATE(AS$387,ROW()-2)>AS$388,"",IFERROR((INDEX($AL$2:$AL$441,MATCH(EDATE(AS$387,ROW()-2),$AJ$2:$AJ$441,0))-INDEX($AL$2:$AL$441,MATCH(EDATE(AS$387,-1),$AJ$2:$AJ$441,0)))*100,"")) -> 1.2807898 | AT2: =IF(EDATE(AT$387,ROW()-2)>AT$388,"",IFERROR((INDEX($AL$2:$AL$441,MATCH(EDATE(AT$387,ROW()-2),$AJ$2:$AJ$441,0))-INDEX($AL$2:$AL$441,MATCH(EDATE(AT$387,-1),$AJ$2:$AJ$441,0)))*100,"")) -> -1.4212495 | AU2: =IF(EDATE(AU$387,ROW()-2)>AU$388,"",IFERROR((INDEX($AL$2:$AL$441,MATCH(EDATE(AU$387,ROW()-2),$AJ$2:$AJ$441,0))-INDEX($AL$2:$AL$441,MATCH(EDATE(AU$387,-1),$AJ$2:$AJ$441,0)))*100,"")) -> -2.6150073
A3: 33270 | B3: 4.66 | C3: - | D3: - | E3: =A3 -> 33270 | I3: =A3 -> 33270 | O3: 34731 | P3: {=IF(OR($O3<P$387,$O3>P$388),"",IFERROR(IF($O3=P$387,100,P2)*INDEX($B$2:$B$428,MATCH($O3,$A$2:$A$428,0))/INDEX($B$2:$B$428,MATCH($O3,$A$2:$A$428,0)-1),""))} -> 103.75395 | Q3: {=IF(OR($O3<Q$387,$O3>Q$388),"",IFERROR(IF($O3=Q$387,100,Q2)*INDEX($B$2:$B$428,MATCH($O3,$A$2:$A$428,0))/INDEX($B$2:$B$428,MATCH($O3,$A$2:$A$428,0)-1),""))} | R3: {=IF(OR($O3<R$387,$O3>R$388),"",IFERROR(IF($O3=R$387,100,R2)*INDEX($B$2:$B$428,MATCH($O3,$A$2:$A$428,0))/INDEX($B$2:$B$428,MATCH($O3,$A$2:$A$428,0)-1),""))} | S3: {=IF(OR($O3<S$387,$O3>S$388),"",IFERROR(IF($O3=S$387,100,S2)*INDEX($B$2:$B$428,MATCH($O3,$A$2:$A$428,0))/INDEX($B$2:$B$428,MATCH($O3,$A$2:$A$428,0)-1),""))} | T3: {=IF(OR($O3<T$387,$O3>T$388),"",IFERROR(IF($O3=T$387,100,T2)*INDEX($B$2:$B$428,MATCH($O3,$A$2:$A$428,0))/INDEX($B$2:$B$428,MATCH($O3,$A$2:$A$428,0)-1),""))} | U3: {=IF(OR($O3<U$387,$O3>U$388),"",IFERROR(IF($O3=U$387,100,U2)*INDEX($B$2:$B$428,MATCH($O3,$A$2:$A$428,0))/INDEX($B$2:$B$428,MATCH($O3,$A$2:$A$428,0)-1),""))} | V3: {=IF(OR($O3<V$387,$O3>V$388),"",IFERROR(IF($O3=V$387,100,V2)*INDEX($B$2:$B$428,MATCH($O3,$A$2:$A$428,0))/INDEX($B$2:$B$428,MATCH($O3,$A$2:$A$428,0)-1),""))} | W3: {=IF(OR($O3<W$387,$O3>W$388),"",IFERROR(IF($O3=W$387,100,W2)*INDEX($B$2:$B$428,MATCH($O3,$A$2:$A$428,0))/INDEX($B$2:$B$428,MATCH($O3,$A$2:$A$428,0)-1),""))} | X3: {=IF(OR($O3<X$387,$O3>X$388),"",IFERROR(IF($O3=X$387,100,X2)*INDEX($B$2:$B$428,MATCH($O3,$A$2:$A$428,0))/INDEX($B$2:$B$428,MATCH($O3,$A$2:$A$428,0)-1),""))} | AA3: {=IF(EDATE(AA$387,ROW()-2)>AA$388,"",IFERROR(IF(ROW()=2,100,AA2)*INDEX($D$2:$D$428,MATCH(EDATE(AA$387,ROW()-2),$A$2:$A$428,0))/INDEX($D$2:$D$428,MATCH(EDATE(AA$387,ROW()-2),$A$2:$A$428,0)-1),""))} -> 117.37863 | AB3: {=IF(EDATE(AB$387,ROW()-2)>AB$388,"",IFERROR(IF(ROW()=2,100,AB2)*INDEX($D$2:$D$428,MATCH(EDATE(AB$387,ROW()-2),$A$2:$A$428,0))/INDEX($D$2:$D$428,MATCH(EDATE(AB$387,ROW()-2),$A$2:$A$428,0)-1),""))} -> 104.62642 | AC3: {=IF(EDATE(AC$387,ROW()-2)>AC$388,"",IFERROR(IF(ROW()=2,100,AC2)*INDEX($D$2:$D$428,MATCH(EDATE(AC$387,ROW()-2),$A$2:$A$428,0))/INDEX($D$2:$D$428,MATCH(EDATE(AC$387,ROW()-2),$A$2:$A$428,0)-1),""))} -> 102.21773 | AD3: {=IF(EDATE(AD$387,ROW()-2)>AD$388,"",IFERROR(IF(ROW()=2,100,AD2)*INDEX($D$2:$D$428,MATCH(EDATE(AD$387,ROW()-2),$A$2:$A$428,0))/INDEX($D$2:$D$428,MATCH(EDATE(AD$387,ROW()-2),$A$2:$A$428,0)-1),""))} -> 98.893977 | AE3: {=IF(EDATE(AE$387,ROW()-2)>AE$388,"",IFERROR(IF(ROW()=2,100,AE2)*INDEX($D$2:$D$428,MATCH(EDATE(AE$387,ROW()-2),$A$2:$A$428,0))/INDEX($D$2:$D$428,MATCH(EDATE(AE$387,ROW()-2),$A$2:$A$428,0)-1),""))} -> 100.33763 | AF3: {=IF(EDATE(AF$387,ROW()-2)>AF$388,"",IFERROR(IF(ROW()=2,100,AF2)*INDEX($D$2:$D$428,MATCH(EDATE(AF$387,ROW()-2),$A$2:$A$428,0))/INDEX($D$2:$D$428,MATCH(EDATE(AF$387,ROW()-2),$A$2:$A$428,0)-1),""))} -> 104.18338 | AG3: {=IF(EDATE(AG$387,ROW()-2)>AG$388,"",IFERROR(IF(ROW()=2,100,AG2)*INDEX($D$2:$D$428,MATCH(EDATE(AG$387,ROW()-2),$A$2:$A$428,0))/INDEX($D$2:$D$428,MATCH(EDATE(AG$387,ROW()-2),$A$2:$A$428,0)-1),""))} -> 100.33612 | AH3: {=IF(EDATE(AH$387,ROW()-2)>AH$388,"",IFERROR(IF(ROW()=2,100,AH2)*INDEX($D$2:$D$428,MATCH(EDATE(AH$387,ROW()-2),$A$2:$A$428,0))/INDEX($D$2:$D$428,MATCH(EDATE(AH$387,ROW()-2),$A$2:$A$428,0)-1),""))} -> 99.128938 | AJ3: 32905 | AK3: 1.1 | AN3: =IF(EDATE(AN$387,ROW()-2)>AN$388,"",IFERROR((INDEX($AL$2:$AL$441,MATCH(EDATE(AN$387,ROW()-2),$AJ$2:$AJ$441,0))-INDEX($AL$2:$AL$441,MATCH(EDATE(AN$387,-1),$AJ$2:$AJ$441,0)))*100,"")) -> 8.3986705 | AO3: =IF(EDATE(AO$387,ROW()-2)>AO$388,"",IFERROR((INDEX($AL$2:$AL$441,MATCH(EDATE(AO$387,ROW()-2),$AJ$2:$AJ$441,0))-INDEX($AL$2:$AL$441,MATCH(EDATE(AO$387,-1),$AJ$2:$AJ$441,0)))*100,"")) -> 1.7817643 | AP3: =IF(EDATE(AP$387,ROW()-2)>AP$388,"",IFERROR((INDEX($AL$2:$AL$441,MATCH(EDATE(AP$387,ROW()-2),$AJ$2:$AJ$441,0))-INDEX($AL$2:$AL$441,MATCH(EDATE(AP$387,-1),$AJ$2:$AJ$441,0)))*100,"")) -> 0.10289991 | AQ3: =IF(EDATE(AQ$387,ROW()-2)>AQ$388,"",IFERROR((INDEX($AL$2:$AL$441,MATCH(EDATE(AQ$387,ROW()-2),$AJ$2:$AJ$441,0))-INDEX($AL$2:$AL$441,MATCH(EDATE(AQ$387,-1),$AJ$2:$AJ$441,0)))*100,"")) -> -2.1210324 | AR3: =IF(EDATE(AR$387,ROW()-2)>AR$388,"",IFERROR((INDEX($AL$2:$AL$441,MATCH(EDATE(AR$387,ROW()-2),$AJ$2:$AJ$441,0))-INDEX($AL$2:$AL$441,MATCH(EDATE(AR$387,-1),$AJ$2:$AJ$441,0)))*100,"")) -> -0.14224504 | AS3: =IF(EDATE(AS$387,ROW()-2)>AS$388,"",IFERROR((INDEX($AL$2:$AL$441,MATCH(EDATE(AS$387,ROW()-2),$AJ$2:$AJ$441,0))-INDEX($AL$2:$AL$441,MATCH(EDATE(AS$387,-1),$AJ$2:$AJ$441,0)))*100,"")) -> 2.2971152 | AT3: =IF(EDATE(AT$387,ROW()-2)>AT$388,"",IFERROR((INDEX($AL$2:$AL$441,MATCH(EDATE(AT$387,ROW()-2),$AJ$2:$AJ$441,0))-INDEX($AL$2:$AL$441,MATCH(EDATE(AT$387,-1),$AJ$2:$AJ$441,0)))*100,"")) -> -0.46569564 | AU3: =IF(EDATE(AU$387,ROW()-2)>AU$388,"",IFERROR((INDEX($AL$2:$AL$441,MATCH(EDATE(AU$387,ROW()-2),$AJ$2:$AJ$441,0))-INDEX($AL$2:$AL$441,MATCH(EDATE(AU$387,-1),$AJ$2:$AJ$441,0)))*100,"")) -> -2.0653267
A4: 33298 | B4: 4.93 | C4: - | D4: - | E4: =A4 -> 33298 | I4: =A4 -> 33298 | O4: 34759 | P4: {=IF(OR($O4<P$387,$O4>P$388),"",IFERROR(IF($O4=P$387,100,P3)*INDEX($B$2:$B$428,MATCH($O4,$A$2:$A$428,0))/INDEX($B$2:$B$428,MATCH($O4,$A$2:$A$428,0)-1),""))} -> 108.29393 | Q4: {=IF(OR($O4<Q$387,$O4>Q$388),"",IFERROR(IF($O4=Q$387,100,Q3)*INDEX($B$2:$B$428,MATCH($O4,$A$2:$A$428,0))/INDEX($B$2:$B$428,MATCH($O4,$A$2:$A$428,0)-1),""))} | R4: {=IF(OR($O4<R$387,$O4>R$388),"",IFERROR(IF($O4=R$387,100,R3)*INDEX($B$2:$B$428,MATCH($O4,$A$2:$A$428,0))/INDEX($B$2:$B$428,MATCH($O4,$A$2:$A$428,0)-1),""))} | S4: {=IF(OR($O4<S$387,$O4>S$388),"",IFERROR(IF($O4=S$387,100,S3)*INDEX($B$2:$B$428,MATCH($O4,$A$2:$A$428,0))/INDEX($B$2:$B$428,MATCH($O4,$A$2:$A$428,0)-1),""))} | T4: {=IF(OR($O4<T$387,$O4>T$388),"",IFERROR(IF($O4=T$387,100,T3)*INDEX($B$2:$B$428,MATCH($O4,$A$2:$A$428,0))/INDEX($B$2:$B$428,MATCH($O4,$A$2:$A$428,0)-1),""))} | U4: {=IF(OR($O4<U$387,$O4>U$388),"",IFERROR(IF($O4=U$387,100,U3)*INDEX($B$2:$B$428,MATCH($O4,$A$2:$A$428,0))/INDEX($B$2:$B$428,MATCH($O4,$A$2:$A$428,0)-1),""))} | V4: {=IF(OR($O4<V$387,$O4>V$388),"",IFERROR(IF($O4=V$387,100,V3)*INDEX($B$2:$B$428,MATCH($O4,$A$2:$A$428,0))/INDEX($B$2:$B$428,MATCH($O4,$A$2:$A$428,0)-1),""))} | W4: {=IF(OR($O4<W$387,$O4>W$388),"",IFERROR(IF($O4=W$387,100,W3)*INDEX($B$2:$B$428,MATCH($O4,$A$2:$A$428,0))/INDEX($B$2:$B$428,MATCH($O4,$A$2:$A$428,0)-1),""))} | X4: {=IF(OR($O4<X$387,$O4>X$388),"",IFERROR(IF($O4=X$387,100,X3)*INDEX($B$2:$B$428,MATCH($O4,$A$2:$A$428,0))/INDEX($B$2:$B$428,MATCH($O4,$A$2:$A$428,0)-1),""))} | AA4: {=IF(EDATE(AA$387,ROW()-2)>AA$388,"",IFERROR(IF(ROW()=2,100,AA3)*INDEX($D$2:$D$428,MATCH(EDATE(AA$387,ROW()-2),$A$2:$A$428,0))/INDEX($D$2:$D$428,MATCH(EDATE(AA$387,ROW()-2),$A$2:$A$428,0)-1),""))} -> 115.15894 | AB4: {=IF(EDATE(AB$387,ROW()-2)>AB$388,"",IFERROR(IF(ROW()=2,100,AB3)*INDEX($D$2:$D$428,MATCH(EDATE(AB$387,ROW()-2),$A$2:$A$428,0))/INDEX($D$2:$D$428,MATCH(EDATE(AB$387,ROW()-2),$A$2:$A$428,0)-1),""))} -> 103.70541 | AC4: {=IF(EDATE(AC$387,ROW()-2)>AC$388,"",IFERROR(IF(ROW()=2,100,AC3)*INDEX($D$2:$D$428,MATCH(EDATE(AC$387,ROW()-2),$A$2:$A$428,0))/INDEX($D$2:$D$428,MATCH(EDATE(AC$387,ROW()-2),$A$2:$A$428,0)-1),""))} -> 103.03178 | AD4: {=IF(EDATE(AD$387,ROW()-2)>AD$388,"",IFERROR(IF(ROW()=2,100,AD3)*INDEX($D$2:$D$428,MATCH(EDATE(AD$387,ROW()-2),$A$2:$A$428,0))/INDEX($D$2:$D$428,MATCH(EDATE(AD$387,ROW()-2),$A$2:$A$428,0)-1),""))} -> 99.922875 | AE4: {=IF(EDATE(AE$387,ROW()-2)>AE$388,"",IFERROR(IF(ROW()=2,100,AE3)*INDEX($D$2:$D$428,MATCH(EDATE(AE$387,ROW()-2),$A$2:$A$428,0))/INDEX($D$2:$D$428,MATCH(EDATE(AE$387,ROW()-2),$A$2:$A$428,0)-1),""))} -> 104.99598 | AF4: {=IF(EDATE(AF$387,ROW()-2)>AF$388,"",IFERROR(IF(ROW()=2,100,AF3)*INDEX($D$2:$D$428,MATCH(EDATE(AF$387,ROW()-2),$A$2:$A$428,0))/INDEX($D$2:$D$428,MATCH(EDATE(AF$387,ROW()-2),$A$2:$A$428,0)-1),""))} -> 103.91462 | AG4: {=IF(EDATE(AG$387,ROW()-2)>AG$388,"",IFERROR(IF(ROW()=2,100,AG3)*INDEX($D$2:$D$428,MATCH(EDATE(AG$387,ROW()-2),$A$2:$A$428,0))/INDEX($D$2:$D$428,MATCH(EDATE(AG$387,ROW()-2),$A$2:$A$428,0)-1),""))} -> 101.17912 | AH4: {=IF(EDATE(AH$387,ROW()-2)>AH$388,"",IFERROR(IF(ROW()=2,100,AH3)*INDEX($D$2:$D$428,MATCH(EDATE(AH$387,ROW()-2),$A$2:$A$428,0))/INDEX($D$2:$D$428,MATCH(EDATE(AH$387,ROW()-2),$A$2:$A$428,0)-1),""))} -> 99.810962 | AJ4: 32933 | AK4: 1.8 | AN4: =IF(EDATE(AN$387,ROW()-2)>AN$388,"",IFERROR((INDEX($AL$2:$AL$441,MATCH(EDATE(AN$387,ROW()-2),$AJ$2:$AJ$441,0))-INDEX($AL$2:$AL$441,MATCH(EDATE(AN$387,-1),$AJ$2:$AJ$441,0)))*100,"")) -> 6.811413 | AO4: =IF(EDATE(AO$387,ROW()-2)>AO$388,"",IFERROR((INDEX($AL$2:$AL$441,MATCH(EDATE(AO$387,ROW()-2),$AJ$2:$AJ$441,0))-INDEX($AL$2:$AL$441,MATCH(EDATE(AO$387,-1),$AJ$2:$AJ$441,0)))*100,"")) -> 0.010880692 | AP4: =IF(EDATE(AP$387,ROW()-2)>AP$388,"",IFERROR((INDEX($AL$2:$AL$441,MATCH(EDATE(AP$387,ROW()-2),$AJ$2:$AJ$441,0))-INDEX($AL$2:$AL$441,MATCH(EDATE(AP$387,-1),$AJ$2:$AJ$441,0)))*100,"")) -> -0.10659931 | AQ4: =IF(EDATE(AQ$387,ROW()-2)>AQ$388,"",IFERROR((INDEX($AL$2:$AL$441,MATCH(EDATE(AQ$387,ROW()-2),$AJ$2:$AJ$441,0))-INDEX($AL$2:$AL$441,MATCH(EDATE(AQ$387,-1),$AJ$2:$AJ$441,0)))*100,"")) -> -2.0696684 | AR4: =IF(EDATE(AR$387,ROW()-2)>AR$388,"",IFERROR((INDEX($AL$2:$AL$441,MATCH(EDATE(AR$387,ROW()-2),$AJ$2:$AJ$441,0))-INDEX($AL$2:$AL$441,MATCH(EDATE(AR$387,-1),$AJ$2:$AJ$441,0)))*100,"")) -> 2.2967036 | AS4: =IF(EDATE(AS$387,ROW()-2)>AS$388,"",IFERROR((INDEX($AL$2:$AL$441,MATCH(EDATE(AS$387,ROW()-2),$AJ$2:$AJ$441,0))-INDEX($AL$2:$AL$441,MATCH(EDATE(AS$387,-1),$AJ$2:$AJ$441,0)))*100,"")) -> 1.929013 | AT4: =IF(EDATE(AT$387,ROW()-2)>AT$388,"",IFERROR((INDEX($AL$2:$AL$441,MATCH(EDATE(AT$387,ROW()-2),$AJ$2:$AJ$441,0))-INDEX($AL$2:$AL$441,MATCH(EDATE(AT$387,-1),$AJ$2:$AJ$441,0)))*100,"")) -> 0.085219079 | AU4: =IF(EDATE(AU$387,ROW()-2)>AU$388,"",IFERROR((INDEX($AL$2:$AL$441,MATCH(EDATE(AU$387,ROW()-2),$AJ$2:$AJ$441,0))-INDEX($AL$2:$AL$441,MATCH(EDATE(AU$387,-1),$AJ$2:$AJ$441,0)))*100,"")) -> -2.2771672
A5: 33329 | B5: 5.2 | C5: - | D5: - | E5: =A5 -> 33329 | I5: =A5 -> 33329 | O5: 34790 | P5: {=IF(OR($O5<P$387,$O5>P$388),"",IFERROR(IF($O5=P$387,100,P4)*INDEX($B$2:$B$428,MATCH($O5,$A$2:$A$428,0))/INDEX($B$2:$B$428,MATCH($O5,$A$2:$A$428,0)-1),""))} -> 109.31173 | Q5: {=IF(OR($O5<Q$387,$O5>Q$388),"",IFERROR(IF($O5=Q$387,100,Q4)*INDEX($B$2:$B$428,MATCH($O5,$A$2:$A$428,0))/INDEX($B$2:$B$428,MATCH($O5,$A$2:$A$428,0)-1),""))} | R5: {=IF(OR($O5<R$387,$O5>R$388),"",IFERROR(IF($O5=R$387,100,R4)*INDEX($B$2:$B$428,MATCH($O5,$A$2:$A$428,0))/INDEX($B$2:$B$428,MATCH($O5,$A$2:$A$428,0)-1),""))} | S5: {=IF(OR($O5<S$387,$O5>S$388),"",IFERROR(IF($O5=S$387,100,S4)*INDEX($B$2:$B$428,MATCH($O5,$A$2:$A$428,0))/INDEX($B$2:$B$428,MATCH($O5,$A$2:$A$428,0)-1),""))} | T5: {=IF(OR($O5<T$387,$O5>T$388),"",IFERROR(IF($O5=T$387,100,T4)*INDEX($B$2:$B$428,MATCH($O5,$A$2:$A$428,0))/INDEX($B$2:$B$428,MATCH($O5,$A$2:$A$428,0)-1),""))} | U5: {=IF(OR($O5<U$387,$O5>U$388),"",IFERROR(IF($O5=U$387,100,U4)*INDEX($B$2:$B$428,MATCH($O5,$A$2:$A$428,0))/INDEX($B$2:$B$428,MATCH($O5,$A$2:$A$428,0)-1),""))} | V5: {=IF(OR($O5<V$387,$O5>V$388),"",IFERROR(IF($O5=V$387,100,V4)*INDEX($B$2:$B$428,MATCH($O5,$A$2:$A$428,0))/INDEX($B$2:$B$428,MATCH($O5,$A$2:$A$428,0)-1),""))} | W5: {=IF(OR($O5<W$387,$O5>W$388),"",IFERROR(IF($O5=W$387,100,W4)*INDEX($B$2:$B$428,MATCH($O5,$A$2:$A$428,0))/INDEX($B$2:$B$428,MATCH($O5,$A$2:$A$428,0)-1),""))} | X5: {=IF(OR($O5<X$387,$O5>X$388),"",IFERROR(IF($O5=X$387,100,X4)*INDEX($B$2:$B$428,MATCH($O5,$A$2:$A$428,0))/INDEX($B$2:$B$428,MATCH($O5,$A$2:$A$428,0)-1),""))} | AA5: {=IF(EDATE(AA$387,ROW()-2)>AA$388,"",IFERROR(IF(ROW()=2,100,AA4)*INDEX($D$2:$D$428,MATCH(EDATE(AA$387,ROW()-2),$A$2:$A$428,0))/INDEX($D$2:$D$428,MATCH(EDATE(AA$387,ROW()-2),$A$2:$A$428,0)-1),""))} -> 119.12887 | AB5: {=IF(EDATE(AB$387,ROW()-2)>AB$388,"",IFERROR(IF(ROW()=2,100,AB4)*INDEX($D$2:$D$428,MATCH(EDATE(AB$387,ROW()-2),$A$2:$A$428,0))/INDEX($D$2:$D$428,MATCH(EDATE(AB$387,ROW()-2),$A$2:$A$428,0)-1),""))} -> 99.859035 | AC5: {=IF(EDATE(AC$387,ROW()-2)>AC$388,"",IFERROR(IF(ROW()=2,100,AC4)*INDEX($D$2:$D$428,MATCH(EDATE(AC$387,ROW()-2),$A$2:$A$428,0))/INDEX($D$2:$D$428,MATCH(EDATE(AC$387,ROW()-2),$A$2:$A$428,0)-1),""))} -> 102.94986 | AD5: {=IF(EDATE(AD$387,ROW()-2)>AD$388,"",IFERROR(IF(ROW()=2,100,AD4)*INDEX($D$2:$D$428,MATCH(EDATE(AD$387,ROW()-2),$A$2:$A$428,0))/INDEX($D$2:$D$428,MATCH(EDATE(AD$387,ROW()-2),$A$2:$A$428,0)-1),""))} -> 102.02594 | AE5: {=IF(EDATE(AE$387,ROW()-2)>AE$388,"",IFERROR(IF(ROW()=2,100,AE4)*INDEX($D$2:$D$428,MATCH(EDATE(AE$387,ROW()-2),$A$2:$A$428,0))/INDEX($D$2:$D$428,MATCH(EDATE(AE$387,ROW()-2),$A$2:$A$428,0)-1),""))} -> 104.9268 | AF5: {=IF(EDATE(AF$387,ROW()-2)>AF$388,"",IFERROR(IF(ROW()=2,100,AF4)*INDEX($D$2:$D$428,MATCH(EDATE(AF$387,ROW()-2),$A$2:$A$428,0))/INDEX($D$2:$D$428,MATCH(EDATE(AF$387,ROW()-2),$A$2:$A$428,0)-1),""))} -> 103.59585 | AG5: {=IF(EDATE(AG$387,ROW()-2)>AG$388,"",IFERROR(IF(ROW()=2,100,AG4)*INDEX($D$2:$D$428,MATCH(EDATE(AG$387,ROW()-2),$A$2:$A$428,0))/INDEX($D$2:$D$428,MATCH(EDATE(AG$387,ROW()-2),$A$2:$A$428,0)-1),""))} -> 101.03907 | AH5: {=IF(EDATE(AH$387,ROW()-2)>AH$388,"",IFERROR(IF(ROW()=2,100,AH4)*INDEX($D$2:$D$428,MATCH(EDATE(AH$387,ROW()-2),$A$2:$A$428,0))/INDEX($D$2:$D$428,MATCH(EDATE(AH$387,ROW()-2),$A$2:$A$428,0)-1),""))} -> 101.6845 | AJ5: 32964 | AK5: 2.5 | AN5: =IF(EDATE(AN$387,ROW()-2)>AN$388,"",IFERROR((INDEX($AL$2:$AL$441,MATCH(EDATE(AN$387,ROW()-2),$AJ$2:$AJ$441,0))-INDEX($AL$2:$AL$441,MATCH(EDATE(AN$387,-1),$AJ$2:$AJ$441,0)))*100,"")) -> 8.4089712 | AO5: =IF(EDATE(AO$387,ROW()-2)>AO$388,"",IFERROR((INDEX($AL$2:$AL$441,MATCH(EDATE(AO$387,ROW()-2),$AJ$2:$AJ$441,0))-INDEX($AL$2:$AL$441,MATCH(EDATE(AO$387,-1),$AJ$2:$AJ$441,0)))*100,"")) -> -3.7775867 | AP5: =IF(EDATE(AP$387,ROW()-2)>AP$388,"",IFERROR((INDEX($AL$2:$AL$441,MATCH(EDATE(AP$387,ROW()-2),$AJ$2:$AJ$441,0))-INDEX($AL$2:$AL$441,MATCH(EDATE(AP$387,-1),$AJ$2:$AJ$441,0)))*100,"")) -> -0.93480355 | AQ5: =IF(EDATE(AQ$387,ROW()-2)>AQ$388,"",IFERROR((INDEX($AL$2:$AL$441,MATCH(EDATE(AQ$387,ROW()-2),$AJ$2:$AJ$441,0))-INDEX($AL$2:$AL$441,MATCH(EDATE(AQ$387,-1),$AJ$2:$AJ$441,0)))*100,"")) -> -1.4515228 | AR5: =IF(EDATE(AR$387,ROW()-2)>AR$388,"",IFERROR((INDEX($AL$2:$AL$441,MATCH(EDATE(AR$387,ROW()-2),$AJ$2:$AJ$441,0))-INDEX($AL$2:$AL$441,MATCH(EDATE(AR$387,-1),$AJ$2:$AJ$441,0)))*100,"")) -> 2.0669178 | AS5: =IF(EDATE(AS$387,ROW()-2)>AS$388,"",IFERROR((INDEX($AL$2:$AL$441,MATCH(EDATE(AS$387,ROW()-2),$AJ$2:$AJ$441,0))-INDEX($AL$2:$AL$441,MATCH(EDATE(AS$387,-1),$AJ$2:$AJ$441,0)))*100,"")) -> 1.3632367 | AT5: =IF(EDATE(AT$387,ROW()-2)>AT$388,"",IFERROR((INDEX($AL$2:$AL$441,MATCH(EDATE(AT$387,ROW()-2),$AJ$2:$AJ$441,0))-INDEX($AL$2:$AL$441,MATCH(EDATE(AT$387,-1),$AJ$2:$AJ$441,0)))*100,"")) -> -0.33733217 | AU5: =IF(EDATE(AU$387,ROW()-2)>AU$388,"",IFERROR((INDEX($AL$2:$AL$441,MATCH(EDATE(AU$387,ROW()-2),$AJ$2:$AJ$441,0))-INDEX($AL$2:$AL$441,MATCH(EDATE(AU$387,-1),$AJ$2:$AJ$441,0)))*100,"")) -> -1.3660648
A6: 33359 | B6: 5.57 | C6: - | D6: - | E6: =A6 -> 33359 | I6: =A6 -> 33359 | O6: 34820 | P6: {=IF(OR($O6<P$387,$O6>P$388),"",IFERROR(IF($O6=P$387,100,P5)*INDEX($B$2:$B$428,MATCH($O6,$A$2:$A$428,0))/INDEX($B$2:$B$428,MATCH($O6,$A$2:$A$428,0)-1),""))} -> 107.36157 | Q6: {=IF(OR($O6<Q$387,$O6>Q$388),"",IFERROR(IF($O6=Q$387,100,Q5)*INDEX($B$2:$B$428,MATCH($O6,$A$2:$A$428,0))/INDEX($B$2:$B$428,MATCH($O6,$A$2:$A$428,0)-1),""))} | R6: {=IF(OR($O6<R$387,$O6>R$388),"",IFERROR(IF($O6=R$387,100,R5)*INDEX($B$2:$B$428,MATCH($O6,$A$2:$A$428,0))/INDEX($B$2:$B$428,MATCH($O6,$A$2:$A$428,0)-1),""))} | S6: {=IF(OR($O6<S$387,$O6>S$388),"",IFERROR(IF($O6=S$387,100,S5)*INDEX($B$2:$B$428,MATCH($O6,$A$2:$A$428,0))/INDEX($B$2:$B$428,MATCH($O6,$A$2:$A$428,0)-1),""))} | T6: {=IF(OR($O6<T$387,$O6>T$388),"",IFERROR(IF($O6=T$387,100,T5)*INDEX($B$2:$B$428,MATCH($O6,$A$2:$A$428,0))/INDEX($B$2:$B$428,MATCH($O6,$A$2:$A$428,0)-1),""))} | U6: {=IF(OR($O6<U$387,$O6>U$388),"",IFERROR(IF($O6=U$387,100,U5)*INDEX($B$2:$B$428,MATCH($O6,$A$2:$A$428,0))/INDEX($B$2:$B$428,MATCH($O6,$A$2:$A$428,0)-1),""))} | V6: {=IF(OR($O6<V$387,$O6>V$388),"",IFERROR(IF($O6=V$387,100,V5)*INDEX($B$2:$B$428,MATCH($O6,$A$2:$A$428,0))/INDEX($B$2:$B$428,MATCH($O6,$A$2:$A$428,0)-1),""))} | W6: {=IF(OR($O6<W$387,$O6>W$388),"",IFERROR(IF($O6=W$387,100,W5)*INDEX($B$2:$B$428,MATCH($O6,$A$2:$A$428,0))/INDEX($B$2:$B$428,MATCH($O6,$A$2:$A$428,0)-1),""))} | X6: {=IF(OR($O6<X$387,$O6>X$388),"",IFERROR(IF($O6=X$387,100,X5)*INDEX($B$2:$B$428,MATCH($O6,$A$2:$A$428,0))/INDEX($B$2:$B$428,MATCH($O6,$A$2:$A$428,0)-1),""))} | AA6: {=IF(EDATE(AA$387,ROW()-2)>AA$388,"",IFERROR(IF(ROW()=2,100,AA5)*INDEX($D$2:$D$428,MATCH(EDATE(AA$387,ROW()-2),$A$2:$A$428,0))/INDEX($D$2:$D$428,MATCH(EDATE(AA$387,ROW()-2),$A$2:$A$428,0)-1),""))} -> 111.05869 | AB6: {=IF(EDATE(AB$387,ROW()-2)>AB$388,"",IFERROR(IF(ROW()=2,100,AB5)*INDEX($D$2:$D$428,MATCH(EDATE(AB$387,ROW()-2),$A$2:$A$428,0))/INDEX($D$2:$D$428,MATCH(EDATE(AB$387,ROW()-2),$A$2:$A$428,0)-1),""))} -> 102.85897 | AC6: {=IF(EDATE(AC$387,ROW()-2)>AC$388,"",IFERROR(IF(ROW()=2,100,AC5)*INDEX($D$2:$D$428,MATCH(EDATE(AC$387,ROW()-2),$A$2:$A$428,0))/INDEX($D$2:$D$428,MATCH(EDATE(AC$387,ROW()-2),$A$2:$A$428,0)-1),""))} -> 104.6563 | AD6: {=IF(EDATE(AD$387,ROW()-2)>AD$388,"",IFERROR(IF(ROW()=2,100,AD5)*INDEX($D$2:$D$428,MATCH(EDATE(AD$387,ROW()-2),$A$2:$A$428,0))/INDEX($D$2:$D$428,MATCH(EDATE(AD$387,ROW()-2),$A$2:$A$428,0)-1),""))} -> 102.45477 | AE6: {=IF(EDATE(AE$387,ROW()-2)>AE$388,"",IFERROR(IF(ROW()=2,100,AE5)*INDEX($D$2:$D$428,MATCH(EDATE(AE$387,ROW()-2),$A$2:$A$428,0))/INDEX($D$2:$D$428,MATCH(EDATE(AE$387,ROW()-2),$A$2:$A$428,0)-1),""))} -> 106.18639 | AF6: {=IF(EDATE(AF$387,ROW()-2)>AF$388,"",IFERROR(IF(ROW()=2,100,AF5)*INDEX($D$2:$D$428,MATCH(EDATE(AF$387,ROW()-2),$A$2:$A$428,0))/INDEX($D$2:$D$428,MATCH(EDATE(AF$387,ROW()-2),$A$2:$A$428,0)-1),""))} -> 106.70506 | AG6: {=IF(EDATE(AG$387,ROW()-2)>AG$388,"",IFERROR(IF(ROW()=2,100,AG5)*INDEX($D$2:$D$428,MATCH(EDATE(AG$387,ROW()-2),$A$2:$A$428,0))/INDEX($D$2:$D$428,MATCH(EDATE(AG$387,ROW()-2),$A$2:$A$428,0)-1),""))} -> 100.77708 | AH6: {=IF(EDATE(AH$387,ROW()-2)>AH$388,"",IFERROR(IF(ROW()=2,100,AH5)*INDEX($D$2:$D$428,MATCH(EDATE(AH$387,ROW()-2),$A$2:$A$428,0))/INDEX($D$2:$D$428,MATCH(EDATE(AH$387,ROW()-2),$A$2:$A$428,0)-1),""))} -> 101.62747 | AJ6: 32994 | AK6: 3.3 | AN6: =IF(EDATE(AN$387,ROW()-2)>AN$388,"",IFERROR((INDEX($AL$2:$AL$441,MATCH(EDATE(AN$387,ROW()-2),$AJ$2:$AJ$441,0))-INDEX($AL$2:$AL$441,MATCH(EDATE(AN$387,-1),$AJ$2:$AJ$441,0)))*100,"")) -> 4.197508 | AO6: =IF(EDATE(AO$387,ROW()-2)>AO$388,"",IFERROR((INDEX($AL$2:$AL$441,MATCH(EDATE(AO$387,ROW()-2),$AJ$2:$AJ$441,0))-INDEX($AL$2:$AL$441,MATCH(EDATE(AO$387,-1),$AJ$2:$AJ$441,0)))*100,"")) -> -2.3827381 | AP6: =IF(EDATE(AP$387,ROW()-2)>AP$388,"",IFERROR((INDEX($AL$2:$AL$441,MATCH(EDATE(AP$387,ROW()-2),$AJ$2:$AJ$441,0))-INDEX($AL$2:$AL$441,MATCH(EDATE(AP$387,-1),$AJ$2:$AJ$441,0)))*100,"")) -> -0.61180883 | AQ6: =IF(EDATE(AQ$387,ROW()-2)>AQ$388,"",IFERROR((INDEX($AL$2:$AL$441,MATCH(EDATE(AQ$387,ROW()-2),$AJ$2:$AJ$441,0))-INDEX($AL$2:$AL$441,MATCH(EDATE(AQ$387,-1),$AJ$2:$AJ$441,0)))*100,"")) -> -1.9747525 | AR6: =IF(EDATE(AR$387,ROW()-2)>AR$388,"",IFERROR((INDEX($AL$2:$AL$441,MATCH(EDATE(AR$387,ROW()-2),$AJ$2:$AJ$441,0))-INDEX($AL$2:$AL$441,MATCH(EDATE(AR$387,-1),$AJ$2:$AJ$441,0)))*100,"")) -> 2.7163943 | AS6: =IF(EDATE(AS$387,ROW()-2)>AS$388,"",IFERROR((INDEX($AL$2:$AL$441,MATCH(EDATE(AS$387,ROW()-2),$AJ$2:$AJ$441,0))-INDEX($AL$2:$AL$441,MATCH(EDATE(AS$387,-1),$AJ$2:$AJ$441,0)))*100,"")) -> 3.2344188 | AT6: =IF(EDATE(AT$387,ROW()-2)>AT$388,"",IFERROR((INDEX($AL$2:$AL$441,MATCH(EDATE(AT$387,ROW()-2),$AJ$2:$AJ$441,0))-INDEX($AL$2:$AL$441,MATCH(EDATE(AT$387,-1),$AJ$2:$AJ$441,0)))*100,"")) -> -1.1933669 | AU6: =IF(EDATE(AU$387,ROW()-2)>AU$388,"",IFERROR((INDEX($AL$2:$AL$441,MATCH(EDATE(AU$387,ROW()-2),$AJ$2:$AJ$441,0))-INDEX($AL$2:$AL$441,MATCH(EDATE(AU$387,-1),$AJ$2:$AJ$441,0)))*100,"")) -> -1.9641486
A7: 33390 | B7: 6.12 | C7: - | D7: - | E7: =A7 -> 33390 | I7: =A7 -> 33390 | O7: 34851 | P7: {=IF(OR($O7<P$387,$O7>P$388),"",IFERROR(IF($O7=P$387,100,P6)*INDEX($B$2:$B$428,MATCH($O7,$A$2:$A$428,0))/INDEX($B$2:$B$428,MATCH($O7,$A$2:$A$428,0)-1),""))} -> 115.2133 | Q7: {=IF(OR($O7<Q$387,$O7>Q$388),"",IFERROR(IF($O7=Q$387,100,Q6)*INDEX($B$2:$B$428,MATCH($O7,$A$2:$A$428,0))/INDEX($B$2:$B$428,MATCH($O7,$A$2:$A$428,0)-1),""))} | R7: {=IF(OR($O7<R$387,$O7>R$388),"",IFERROR(IF($O7=R$387,100,R6)*INDEX($B$2:$B$428,MATCH($O7,$A$2:$A$428,0))/INDEX($B$2:$B$428,MATCH($O7,$A$2:$A$428,0)-1),""))} | S7: {=IF(OR($O7<S$387,$O7>S$388),"",IFERROR(IF($O7=S$387,100,S6)*INDEX($B$2:$B$428,MATCH($O7,$A$2:$A$428,0))/INDEX($B$2:$B$428,MATCH($O7,$A$2:$A$428,0)-1),""))} | T7: {=IF(OR($O7<T$387,$O7>T$388),"",IFERROR(IF($O7=T$387,100,T6)*INDEX($B$2:$B$428,MATCH($O7,$A$2:$A$428,0))/INDEX($B$2:$B$428,MATCH($O7,$A$2:$A$428,0)-1),""))} | U7: {=IF(OR($O7<U$387,$O7>U$388),"",IFERROR(IF($O7=U$387,100,U6)*INDEX($B$2:$B$428,MATCH($O7,$A$2:$A$428,0))/INDEX($B$2:$B$428,MATCH($O7,$A$2:$A$428,0)-1),""))} | V7: {=IF(OR($O7<V$387,$O7>V$388),"",IFERROR(IF($O7=V$387,100,V6)*INDEX($B$2:$B$428,MATCH($O7,$A$2:$A$428,0))/INDEX($B$2:$B$428,MATCH($O7,$A$2:$A$428,0)-1),""))} | W7: {=IF(OR($O7<W$387,$O7>W$388),"",IFERROR(IF($O7=W$387,100,W6)*INDEX($B$2:$B$428,MATCH($O7,$A$2:$A$428,0))/INDEX($B$2:$B$428,MATCH($O7,$A$2:$A$428,0)-1),""))} | X7: {=IF(OR($O7<X$387,$O7>X$388),"",IFERROR(IF($O7=X$387,100,X6)*INDEX($B$2:$B$428,MATCH($O7,$A$2:$A$428,0))/INDEX($B$2:$B$428,MATCH($O7,$A$2:$A$428,0)-1),""))} | AA7: {=IF(EDATE(AA$387,ROW()-2)>AA$388,"",IFERROR(IF(ROW()=2,100,AA6)*INDEX($D$2:$D$428,MATCH(EDATE(AA$387,ROW()-2),$A$2:$A$428,0))/INDEX($D$2:$D$428,MATCH(EDATE(AA$387,ROW()-2),$A$2:$A$428,0)-1),""))} -> 114.36854 | AB7: {=IF(EDATE(AB$387,ROW()-2)>AB$388,"",IFERROR(IF(ROW()=2,100,AB6)*INDEX($D$2:$D$428,MATCH(EDATE(AB$387,ROW()-2),$A$2:$A$428,0))/INDEX($D$2:$D$428,MATCH(EDATE(AB$387,ROW()-2),$A$2:$A$428,0)-1),""))} -> 103.31502 | AC7: {=IF(EDATE(AC$387,ROW()-2)>AC$388,"",IFERROR(IF(ROW()=2,100,AC6)*INDEX($D$2:$D$428,MATCH(EDATE(AC$387,ROW()-2),$A$2:$A$428,0))/INDEX($D$2:$D$428,MATCH(EDATE(AC$387,ROW()-2),$A$2:$A$428,0)-1),""))} -> 106.34786 | AD7: {=IF(EDATE(AD$387,ROW()-2)>AD$388,"",IFERROR(IF(ROW()=2,100,AD6)*INDEX($D$2:$D$428,MATCH(EDATE(AD$387,ROW()-2),$A$2:$A$428,0))/INDEX($D$2:$D$428,MATCH(EDATE(AD$387,ROW()-2),$A$2:$A$428,0)-1),""))} -> 104.70127 | AE7: {=IF(EDATE(AE$387,ROW()-2)>AE$388,"",IFERROR(IF(ROW()=2,100,AE6)*INDEX($D$2:$D$428,MATCH(EDATE(AE$387,ROW()-2),$A$2:$A$428,0))/INDEX($D$2:$D$428,MATCH(EDATE(AE$387,ROW()-2),$A$2:$A$428,0)-1),""))} -> 108.91255 | AF7: {=IF(EDATE(AF$387,ROW()-2)>AF$388,"",IFERROR(IF(ROW()=2,100,AF6)*INDEX($D$2:$D$428,MATCH(EDATE(AF$387,ROW()-2),$A$2:$A$428,0))/INDEX($D$2:$D$428,MATCH(EDATE(AF$387,ROW()-2),$A$2:$A$428,0)-1),""))} -> 106.58646 | AG7: {=IF(EDATE(AG$387,ROW()-2)>AG$388,"",IFERROR(IF(ROW()=2,100,AG6)*INDEX($D$2:$D$428,MATCH(EDATE(AG$387,ROW()-2),$A$2:$A$428,0))/INDEX($D$2:$D$428,MATCH(EDATE(AG$387,ROW()-2),$A$2:$A$428,0)-1),""))} -> 102.37138 | AH7: {=IF(EDATE(AH$387,ROW()-2)>AH$388,"",IFERROR(IF(ROW()=2,100,AH6)*INDEX($D$2:$D$428,MATCH(EDATE(AH$387,ROW()-2),$A$2:$A$428,0))/INDEX($D$2:$D$428,MATCH(EDATE(AH$387,ROW()-2),$A$2:$A$428,0)-1),""))} -> 103.87684 | AJ7: 33025 | AK7: 4 | AN7: =IF(EDATE(AN$387,ROW()-2)>AN$388,"",IFERROR((INDEX($AL$2:$AL$441,MATCH(EDATE(AN$387,ROW()-2),$AJ$2:$AJ$441,0))-INDEX($AL$2:$AL$441,MATCH(EDATE(AN$387,-1),$AJ$2:$AJ$441,0)))*100,"")) -> 5.4928322 | AO7: =IF(EDATE(AO$387,ROW()-2)>AO$388,"",IFERROR((INDEX($AL$2:$AL$441,MATCH(EDATE(AO$387,ROW()-2),$AJ$2:$AJ$441,0))-INDEX($AL$2:$AL$441,MATCH(EDATE(AO$387,-1),$AJ$2:$AJ$441,0)))*100,"")) -> -2.7290731 | AP7: =IF(EDATE(AP$387,ROW()-2)>AP$388,"",IFERROR((INDEX($AL$2:$AL$441,MATCH(EDATE(AP$387,ROW()-2),$AJ$2:$AJ$441,0))-INDEX($AL$2:$AL$441,MATCH(EDATE(AP$387,-1),$AJ$2:$AJ$441,0)))*100,"")) -> -0.32313009 | AQ7: =IF(EDATE(AQ$387,ROW()-2)>AQ$388,"",IFERROR((INDEX($AL$2:$AL$441,MATCH(EDATE(AQ$387,ROW()-2),$AJ$2:$AJ$441,0))-INDEX($AL$2:$AL$441,MATCH(EDATE(AQ$387,-1),$AJ$2:$AJ$441,0)))*100,"")) -> -1.3514368 | AR7: =IF(EDATE(AR$387,ROW()-2)>AR$388,"",IFERROR((INDEX($AL$2:$AL$441,MATCH(EDATE(AR$387,ROW()-2),$AJ$2:$AJ$441,0))-INDEX($AL$2:$AL$441,MATCH(EDATE(AR$387,-1),$AJ$2:$AJ$441,0)))*100,"")) -> 4.033834 | AS7: =IF(EDATE(AS$387,ROW()-2)>AS$388,"",IFERROR((INDEX($AL$2:$AL$441,MATCH(EDATE(AS$387,ROW()-2),$AJ$2:$AJ$441,0))-INDEX($AL$2:$AL$441,MATCH(EDATE(AS$387,-1),$AJ$2:$AJ$441,0)))*100,"")) -> 2.932735 | AT7: =IF(EDATE(AT$387,ROW()-2)>AT$388,"",IFERROR((INDEX($AL$2:$AL$441,MATCH(EDATE(AT$387,ROW()-2),$AJ$2:$AJ$441,0))-INDEX($AL$2:$AL$441,MATCH(EDATE(AT$387,-1),$AJ$2:$AJ$441,0)))*100,"")) -> -0.024091328 | AU7: =IF(EDATE(AU$387,ROW()-2)>AU$388,"",IFERROR((INDEX($AL$2:$AL$441,MATCH(EDATE(AU$387,ROW()-2),$AJ$2:$AJ$441,0))-INDEX($AL$2:$AL$441,MATCH(EDATE(AU$387,-1),$AJ$2:$AJ$441,0)))*100,"")) -> -0.64290953
A8: 33420 | B8: 6.61 | C8: - | D8: - | E8: =A8 -> 33420 | I8: =A8 -> 33420 | O8: 34881 | P8: {=IF(OR($O8<P$387,$O8>P$388),"",IFERROR(IF($O8=P$387,100,P7)*INDEX($B$2:$B$428,MATCH($O8,$A$2:$A$428,0))/INDEX($B$2:$B$428,MATCH($O8,$A$2:$A$428,0)-1),""))} -> 119.33292 | Q8: {=IF(OR($O8<Q$387,$O8>Q$388),"",IFERROR(IF($O8=Q$387,100,Q7)*INDEX($B$2:$B$428,MATCH($O8,$A$2:$A$428,0))/INDEX($B$2:$B$428,MATCH($O8,$A$2:$A$428,0)-1),""))} | R8: {=IF(OR($O8<R$387,$O8>R$388),"",IFERROR(IF($O8=R$387,100,R7)*INDEX($B$2:$B$428,MATCH($O8,$A$2:$A$428,0))/INDEX($B$2:$B$428,MATCH($O8,$A$2:$A$428,0)-1),""))} | S8: {=IF(OR($O8<S$387,$O8>S$388),"",IFERROR(IF($O8=S$387,100,S7)*INDEX($B$2:$B$428,MATCH($O8,$A$2:$A$428,0))/INDEX($B$2:$B$428,MATCH($O8,$A$2:$A$428,0)-1),""))} | T8: {=IF(OR($O8<T$387,$O8>T$388),"",IFERROR(IF($O8=T$387,100,T7)*INDEX($B$2:$B$428,MATCH($O8,$A$2:$A$428,0))/INDEX($B$2:$B$428,MATCH($O8,$A$2:$A$428,0)-1),""))} | U8: {=IF(OR($O8<U$387,$O8>U$388),"",IFERROR(IF($O8=U$387,100,U7)*INDEX($B$2:$B$428,MATCH($O8,$A$2:$A$428,0))/INDEX($B$2:$B$428,MATCH($O8,$A$2:$A$428,0)-1),""))} | V8: {=IF(OR($O8<V$387,$O8>V$388),"",IFERROR(IF($O8=V$387,100,V7)*INDEX($B$2:$B$428,MATCH($O8,$A$2:$A$428,0))/INDEX($B$2:$B$428,MATCH($O8,$A$2:$A$428,0)-1),""))} | W8: {=IF(OR($O8<W$387,$O8>W$388),"",IFERROR(IF($O8=W$387,100,W7)*INDEX($B$2:$B$428,MATCH($O8,$A$2:$A$428,0))/INDEX($B$2:$B$428,MATCH($O8,$A$2:$A$428,0)-1),""))} | X8: {=IF(OR($O8<X$387,$O8>X$388),"",IFERROR(IF($O8=X$387,100,X7)*INDEX($B$2:$B$428,MATCH($O8,$A$2:$A$428,0))/INDEX($B$2:$B$428,MATCH($O8,$A$2:$A$428,0)-1),""))} | AA8: {=IF(EDATE(AA$387,ROW()-2)>AA$388,"",IFERROR(IF(ROW()=2,100,AA7)*INDEX($D$2:$D$428,MATCH(EDATE(AA$387,ROW()-2),$A$2:$A$428,0))/INDEX($D$2:$D$428,MATCH(EDATE(AA$387,ROW()-2),$A$2:$A$428,0)-1),""))} -> 115.29875 | AB8: {=IF(EDATE(AB$387,ROW()-2)>AB$388,"",IFERROR(IF(ROW()=2,100,AB7)*INDEX($D$2:$D$428,MATCH(EDATE(AB$387,ROW()-2),$A$2:$A$428,0))/INDEX($D$2:$D$428,MATCH(EDATE(AB$387,ROW()-2),$A$2:$A$428,0)-1),""))} -> 106.07119 | AC8: {=IF(EDATE(AC$387,ROW()-2)>AC$388,"",IFERROR(IF(ROW()=2,100,AC7)*INDEX($D$2:$D$428,MATCH(EDATE(AC$387,ROW()-2),$A$2:$A$428,0))/INDEX($D$2:$D$428,MATCH(EDATE(AC$387,ROW()-2),$A$2:$A$428,0)-1),""))} -> 103.92242 | AD8: {=IF(EDATE(AD$387,ROW()-2)>AD$388,"",IFERROR(IF(ROW()=2,100,AD7)*INDEX($D$2:$D$428,MATCH(EDATE(AD$387,ROW()-2),$A$2:$A$428,0))/INDEX($D$2:$D$428,MATCH(EDATE(AD$387,ROW()-2),$A$2:$A$428,0)-1),""))} -> 101.39214 | AE8: {=IF(EDATE(AE$387,ROW()-2)>AE$388,"",IFERROR(IF(ROW()=2,100,AE7)*INDEX($D$2:$D$428,MATCH(EDATE(AE$387,ROW()-2),$A$2:$A$428,0))/INDEX($D$2:$D$428,MATCH(EDATE(AE$387,ROW()-2),$A$2:$A$428,0)-1),""))} -> 109.35987 | AF8: {=IF(EDATE(AF$387,ROW()-2)>AF$388,"",IFERROR(IF(ROW()=2,100,AF7)*INDEX($D$2:$D$428,MATCH(EDATE(AF$387,ROW()-2),$A$2:$A$428,0))/INDEX($D$2:$D$428,MATCH(EDATE(AF$387,ROW()-2),$A$2:$A$428,0)-1),""))} -> 108.34546 | AG8: {=IF(EDATE(AG$387,ROW()-2)>AG$388,"",IFERROR(IF(ROW()=2,100,AG7)*INDEX($D$2:$D$428,MATCH(EDATE(AG$387,ROW()-2),$A$2:$A$428,0))/INDEX($D$2:$D$428,MATCH(EDATE(AG$387,ROW()-2),$A$2:$A$428,0)-1),""))} -> 101.80535 | AH8: {=IF(EDATE(AH$387,ROW()-2)>AH$388,"",IFERROR(IF(ROW()=2,100,AH7)*INDEX($D$2:$D$428,MATCH(EDATE(AH$387,ROW()-2),$A$2:$A$428,0))/INDEX($D$2:$D$428,MATCH(EDATE(AH$387,ROW()-2),$A$2:$A$428,0)-1),""))} -> 103.14072 | AJ8: 33055 | AK8: 4.9 | AN8: =IF(EDATE(AN$387,ROW()-2)>AN$388,"",IFERROR((INDEX($AL$2:$AL$441,MATCH(EDATE(AN$387,ROW()-2),$AJ$2:$AJ$441,0))-INDEX($AL$2:$AL$441,MATCH(EDATE(AN$387,-1),$AJ$2:$AJ$441,0)))*100,"")) -> 5.7152775 | AO8: =IF(EDATE(AO$387,ROW()-2)>AO$388,"",IFERROR((INDEX($AL$2:$AL$441,MATCH(EDATE(AO$387,ROW()-2),$AJ$2:$AJ$441,0))-INDEX($AL$2:$AL$441,MATCH(EDATE(AO$387,-1),$AJ$2:$AJ$441,0)))*100,"")) -> -1.6016356 | AP8: =IF(EDATE(AP$387,ROW()-2)>AP$388,"",IFERROR((INDEX($AL$2:$AL$441,MATCH(EDATE(AP$387,ROW()-2),$AJ$2:$AJ$441,0))-INDEX($AL$2:$AL$441,MATCH(EDATE(AP$387,-1),$AJ$2:$AJ$441,0)))*100,"")) -> -2.4509417 | AQ8: =IF(EDATE(AQ$387,ROW()-2)>AQ$388,"",IFERROR((INDEX($AL$2:$AL$441,MATCH(EDATE(AQ$387,ROW()-2),$AJ$2:$AJ$441,0))-INDEX($AL$2:$AL$441,MATCH(EDATE(AQ$387,-1),$AJ$2:$AJ$441,0)))*100,"")) -> -3.8238371 | AR8: =IF(EDATE(AR$387,ROW()-2)>AR$388,"",IFERROR((INDEX($AL$2:$AL$441,MATCH(EDATE(AR$387,ROW()-2),$AJ$2:$AJ$441,0))-INDEX($AL$2:$AL$441,MATCH(EDATE(AR$387,-1),$AJ$2:$AJ$441,0)))*100,"")) -> 4.0791211 | AS8: =IF(EDATE(AS$387,ROW()-2)>AS$388,"",IFERROR((INDEX($AL$2:$AL$441,MATCH(EDATE(AS$387,ROW()-2),$AJ$2:$AJ$441,0))-INDEX($AL$2:$AL$441,MATCH(EDATE(AS$387,-1),$AJ$2:$AJ$441,0)))*100,"")) -> 3.7697284 | AT8: =IF(EDATE(AT$387,ROW()-2)>AT$388,"",IFERROR((INDEX($AL$2:$AL$441,MATCH(EDATE(AT$387,ROW()-2),$AJ$2:$AJ$441,0))-INDEX($AL$2:$AL$441,MATCH(EDATE(AT$387,-1),$AJ$2:$AJ$441,0)))*100,"")) -> -0.96003623 | AU8: =IF(EDATE(AU$387,ROW()-2)>AU$388,"",IFERROR((INDEX($AL$2:$AL$441,MATCH(EDATE(AU$387,ROW()-2),$AJ$2:$AJ$441,0))-INDEX($AL$2:$AL$441,MATCH(EDATE(AU$387,-1),$AJ$2:$AJ$441,0)))*100,"")) -> -1.6412093
A9: 33451 | B9: 7.51 | C9: - | D9: - | E9: =A9 -> 33451 | I9: =A9 -> 33451 | O9: 34912 | P9: {=IF(OR($O9<P$387,$O9>P$388),"",IFERROR(IF($O9=P$387,100,P8)*INDEX($B$2:$B$428,MATCH($O9,$A$2:$A$428,0))/INDEX($B$2:$B$428,MATCH($O9,$A$2:$A$428,0)-1),""))} -> 119.17279 | Q9: {=IF(OR($O9<Q$387,$O9>Q$388),"",IFERROR(IF($O9=Q$387,100,Q8)*INDEX($B$2:$B$428,MATCH($O9,$A$2:$A$428,0))/INDEX($B$2:$B$428,MATCH($O9,$A$2:$A$428,0)-1),""))} | R9: {=IF(OR($O9<R$387,$O9>R$388),"",IFERROR(IF($O9=R$387,100,R8)*INDEX($B$2:$B$428,MATCH($O9,$A$2:$A$428,0))/INDEX($B$2:$B$428,MATCH($O9,$A$2:$A$428,0)-1),""))} | S9: {=IF(OR($O9<S$387,$O9>S$388),"",IFERROR(IF($O9=S$387,100,S8)*INDEX($B$2:$B$428,MATCH($O9,$A$2:$A$428,0))/INDEX($B$2:$B$428,MATCH($O9,$A$2:$A$428,0)-1),""))} | T9: {=IF(OR($O9<T$387,$O9>T$388),"",IFERROR(IF($O9=T$387,100,T8)*INDEX($B$2:$B$428,MATCH($O9,$A$2:$A$428,0))/INDEX($B$2:$B$428,MATCH($O9,$A$2:$A$428,0)-1),""))} | U9: {=IF(OR($O9<U$387,$O9>U$388),"",IFERROR(IF($O9=U$387,100,U8)*INDEX($B$2:$B$428,MATCH($O9,$A$2:$A$428,0))/INDEX($B$2:$B$428,MATCH($O9,$A$2:$A$428,0)-1),""))} | V9: {=IF(OR($O9<V$387,$O9>V$388),"",IFERROR(IF($O9=V$387,100,V8)*INDEX($B$2:$B$428,MATCH($O9,$A$2:$A$428,0))/INDEX($B$2:$B$428,MATCH($O9,$A$2:$A$428,0)-1),""))} | W9: {=IF(OR($O9<W$387,$O9>W$388),"",IFERROR(IF($O9=W$387,100,W8)*INDEX($B$2:$B$428,MATCH($O9,$A$2:$A$428,0))/INDEX($B$2:$B$428,MATCH($O9,$A$2:$A$428,0)-1),""))} | X9: {=IF(OR($O9<X$387,$O9>X$388),"",IFERROR(IF($O9=X$387,100,X8)*INDEX($B$2:$B$428,MATCH($O9,$A$2:$A$428,0))/INDEX($B$2:$B$428,MATCH($O9,$A$2:$A$428,0)-1),""))} | AA9: {=IF(EDATE(AA$387,ROW()-2)>AA$388,"",IFERROR(IF(ROW()=2,100,AA8)*INDEX($D$2:$D$428,MATCH(EDATE(AA$387,ROW()-2),$A$2:$A$428,0))/INDEX($D$2:$D$428,MATCH(EDATE(AA$387,ROW()-2),$A$2:$A$428,0)-1),""))} -> 119.32531 | AB9: {=IF(EDATE(AB$387,ROW()-2)>AB$388,"",IFERROR(IF(ROW()=2,100,AB8)*INDEX($D$2:$D$428,MATCH(EDATE(AB$387,ROW()-2),$A$2:$A$428,0))/INDEX($D$2:$D$428,MATCH(EDATE(AB$387,ROW()-2),$A$2:$A$428,0)-1),""))} -> 106.87469 | AC9: {=IF(EDATE(AC$387,ROW()-2)>AC$388,"",IFERROR(IF(ROW()=2,100,AC8)*INDEX($D$2:$D$428,MATCH(EDATE(AC$387,ROW()-2),$A$2:$A$428,0))/INDEX($D$2:$D$428,MATCH(EDATE(AC$387,ROW()-2),$A$2:$A$428,0)-1),""))} -> 105.80494 | AD9: {=IF(EDATE(AD$387,ROW()-2)>AD$388,"",IFERROR(IF(ROW()=2,100,AD8)*INDEX($D$2:$D$428,MATCH(EDATE(AD$387,ROW()-2),$A$2:$A$428,0))/INDEX($D$2:$D$428,MATCH(EDATE(AD$387,ROW()-2),$A$2:$A$428,0)-1),""))} -> 103.28106 | AE9: {=IF(EDATE(AE$387,ROW()-2)>AE$388,"",IFERROR(IF(ROW()=2,100,AE8)*INDEX($D$2:$D$428,MATCH(EDATE(AE$387,ROW()-2),$A$2:$A$428,0))/INDEX($D$2:$D$428,MATCH(EDATE(AE$387,ROW()-2),$A$2:$A$428,0)-1),""))} -> 112.7245 | AF9: {=IF(EDATE(AF$387,ROW()-2)>AF$388,"",IFERROR(IF(ROW()=2,100,AF8)*INDEX($D$2:$D$428,MATCH(EDATE(AF$387,ROW()-2),$A$2:$A$428,0))/INDEX($D$2:$D$428,MATCH(EDATE(AF$387,ROW()-2),$A$2:$A$428,0)-1),""))} -> 112.79935 | AG9: {=IF(EDATE(AG$387,ROW()-2)>AG$388,"",IFERROR(IF(ROW()=2,100,AG8)*INDEX($D$2:$D$428,MATCH(EDATE(AG$387,ROW()-2),$A$2:$A$428,0))/INDEX($D$2:$D$428,MATCH(EDATE(AG$387,ROW()-2),$A$2:$A$428,0)-1),""))} -> 103.94621 | AH9: {=IF(EDATE(AH$387,ROW()-2)>AH$388,"",IFERROR(IF(ROW()=2,100,AH8)*INDEX($D$2:$D$428,MATCH(EDATE(AH$387,ROW()-2),$A$2:$A$428,0))/INDEX($D$2:$D$428,MATCH(EDATE(AH$387,ROW()-2),$A$2:$A$428,0)-1),""))} -> 104.76091 | AJ9: 33086 | AK9: 5.9 | AN9: =IF(EDATE(AN$387,ROW()-2)>AN$388,"",IFERROR((INDEX($AL$2:$AL$441,MATCH(EDATE(AN$387,ROW()-2),$AJ$2:$AJ$441,0))-INDEX($AL$2:$AL$441,MATCH(EDATE(AN$387,-1),$AJ$2:$AJ$441,0)))*100,"")) -> 7.3516433 | AO9: =IF(EDATE(AO$387,ROW()-2)>AO$388,"",IFERROR((INDEX($AL$2:$AL$441,MATCH(EDATE(AO$387,ROW()-2),$AJ$2:$AJ$441,0))-INDEX($AL$2:$AL$441,MATCH(EDATE(AO$387,-1),$AJ$2:$AJ$441,0)))*100,"")) -> -1.8003247 | AP9: =IF(EDATE(AP$387,ROW()-2)>AP$388,"",IFERROR((INDEX($AL$2:$AL$441,MATCH(EDATE(AP$387,ROW()-2),$AJ$2:$AJ$441,0))-INDEX($AL$2:$AL$441,MATCH(EDATE(AP$387,-1),$AJ$2:$AJ$441,0)))*100,"")) -> -1.9296556 | AQ9: =IF(EDATE(AQ$387,ROW()-2)>AQ$388,"",IFERROR((INDEX($AL$2:$AL$441,MATCH(EDATE(AQ$387,ROW()-2),$AJ$2:$AJ$441,0))-INDEX($AL$2:$AL$441,MATCH(EDATE(AQ$387,-1),$AJ$2:$AJ$441,0)))*100,"")) -> -3.3303943 | AR9: =IF(EDATE(AR$387,ROW()-2)>AR$388,"",IFERROR((INDEX($AL$2:$AL$441,MATCH(EDATE(AR$387,ROW()-2),$AJ$2:$AJ$441,0))-INDEX($AL$2:$AL$441,MATCH(EDATE(AR$387,-1),$AJ$2:$AJ$441,0)))*100,"")) -> 5.9030373 | AS9: =IF(EDATE(AS$387,ROW()-2)>AS$388,"",IFERROR((INDEX($AL$2:$AL$441,MATCH(EDATE(AS$387,ROW()-2),$AJ$2:$AJ$441,0))-INDEX($AL$2:$AL$441,MATCH(EDATE(AS$387,-1),$AJ$2:$AJ$441,0)))*100,"")) -> 6.4481898 | AT9: =IF(EDATE(AT$387,ROW()-2)>AT$388,"",IFERROR((INDEX($AL$2:$AL$441,MATCH(EDATE(AT$387,ROW()-2),$AJ$2:$AJ$441,0))-INDEX($AL$2:$AL$441,MATCH(EDATE(AT$387,-1),$AJ$2:$AJ$441,0)))*100,"")) -> 0.42913128 | AU9: =IF(EDATE(AU$387,ROW()-2)>AU$388,"",IFERROR((INDEX($AL$2:$AL$441,MATCH(EDATE(AU$387,ROW()-2),$AJ$2:$AJ$441,0))-INDEX($AL$2:$AL$441,MATCH(EDATE(AU$387,-1),$AJ$2:$AJ$441,0)))*100,"")) -> -0.80893002
A10: 33482 | B10: 9.01 | C10: - | D10: - | E10: =A10 -> 33482 | I10: =A10 -> 33482 | O10: 34943 | P10: {=IF(OR($O10<P$387,$O10>P$388),"",IFERROR(IF($O10=P$387,100,P9)*INDEX($B$2:$B$428,MATCH($O10,$A$2:$A$428,0))/INDEX($B$2:$B$428,MATCH($O10,$A$2:$A$428,0)-1),""))} -> 122.72945 | Q10: {=IF(OR($O10<Q$387,$O10>Q$388),"",IFERROR(IF($O10=Q$387,100,Q9)*INDEX($B$2:$B$428,MATCH($O10,$A$2:$A$428,0))/INDEX($B$2:$B$428,MATCH($O10,$A$2:$A$428,0)-1),""))} | R10: {=IF(OR($O10<R$387,$O10>R$388),"",IFERROR(IF($O10=R$387,100,R9)*INDEX($B$2:$B$428,MATCH($O10,$A$2:$A$428,0))/INDEX($B$2:$B$428,MATCH($O10,$A$2:$A$428,0)-1),""))} | S10: {=IF(OR($O10<S$387,$O10>S$388),"",IFERROR(IF($O10=S$387,100,S9)*INDEX($B$2:$B$428,MATCH($O10,$A$2:$A$428,0))/INDEX($B$2:$B$428,MATCH($O10,$A$2:$A$428,0)-1),""))} | T10: {=IF(OR($O10<T$387,$O10>T$388),"",IFERROR(IF($O10=T$387,100,T9)*INDEX($B$2:$B$428,MATCH($O10,$A$2:$A$428,0))/INDEX($B$2:$B$428,MATCH($O10,$A$2:$A$428,0)-1),""))} | U10: {=IF(OR($O10<U$387,$O10>U$388),"",IFERROR(IF($O10=U$387,100,U9)*INDEX($B$2:$B$428,MATCH($O10,$A$2:$A$428,0))/INDEX($B$2:$B$428,MATCH($O10,$A$2:$A$428,0)-1),""))} | V10: {=IF(OR($O10<V$387,$O10>V$388),"",IFERROR(IF($O10=V$387,100,V9)*INDEX($B$2:$B$428,MATCH($O10,$A$2:$A$428,0))/INDEX($B$2:$B$428,MATCH($O10,$A$2:$A$428,0)-1),""))} | W10: {=IF(OR($O10<W$387,$O10>W$388),"",IFERROR(IF($O10=W$387,100,W9)*INDEX($B$2:$B$428,MATCH($O10,$A$2:$A$428,0))/INDEX($B$2:$B$428,MATCH($O10,$A$2:$A$428,0)-1),""))} | X10: {=IF(OR($O10<X$387,$O10>X$388),"",IFERROR(IF($O10=X$387,100,X9)*INDEX($B$2:$B$428,MATCH($O10,$A$2:$A$428,0))/INDEX($B$2:$B$428,MATCH($O10,$A$2:$A$428,0)-1),""))} | AA10: {=IF(EDATE(AA$387,ROW()-2)>AA$388,"",IFERROR(IF(ROW()=2,100,AA9)*INDEX($D$2:$D$428,MATCH(EDATE(AA$387,ROW()-2),$A$2:$A$428,0))/INDEX($D$2:$D$428,MATCH(EDATE(AA$387,ROW()-2),$A$2:$A$428,0)-1),""))} -> 121.81534 | AB10: {=IF(EDATE(AB$387,ROW()-2)>AB$388,"",IFERROR(IF(ROW()=2,100,AB9)*INDEX($D$2:$D$428,MATCH(EDATE(AB$387,ROW()-2),$A$2:$A$428,0))/INDEX($D$2:$D$428,MATCH(EDATE(AB$387,ROW()-2),$A$2:$A$428,0)-1),""))} -> 108.60739 | AC10: {=IF(EDATE(AC$387,ROW()-2)>AC$388,"",IFERROR(IF(ROW()=2,100,AC9)*INDEX($D$2:$D$428,MATCH(EDATE(AC$387,ROW()-2),$A$2:$A$428,0))/INDEX($D$2:$D$428,MATCH(EDATE(AC$387,ROW()-2),$A$2:$A$428,0)-1),""))} -> 106.32105 | AD10: {=IF(EDATE(AD$387,ROW()-2)>AD$388,"",IFERROR(IF(ROW()=2,100,AD9)*INDEX($D$2:$D$428,MATCH(EDATE(AD$387,ROW()-2),$A$2:$A$428,0))/INDEX($D$2:$D$428,MATCH(EDATE(AD$387,ROW()-2),$A$2:$A$428,0)-1),""))} -> 105.6513 | AE10: {=IF(EDATE(AE$387,ROW()-2)>AE$388,"",IFERROR(IF(ROW()=2,100,AE9)*INDEX($D$2:$D$428,MATCH(EDATE(AE$387,ROW()-2),$A$2:$A$428,0))/INDEX($D$2:$D$428,MATCH(EDATE(AE$387,ROW()-2),$A$2:$A$428,0)-1),""))} -> 116.50817 | AF10: {=IF(EDATE(AF$387,ROW()-2)>AF$388,"",IFERROR(IF(ROW()=2,100,AF9)*INDEX($D$2:$D$428,MATCH(EDATE(AF$387,ROW()-2),$A$2:$A$428,0))/INDEX($D$2:$D$428,MATCH(EDATE(AF$387,ROW()-2),$A$2:$A$428,0)-1),""))} -> 112.19392 | AG10: {=IF(EDATE(AG$387,ROW()-2)>AG$388,"",IFERROR(IF(ROW()=2,100,AG9)*INDEX($D$2:$D$428,MATCH(EDATE(AG$387,ROW()-2),$A$2:$A$428,0))/INDEX($D$2:$D$428,MATCH(EDATE(AG$387,ROW()-2),$A$2:$A$428,0)-1),""))} -> 105.56059 | AH10: {=IF(EDATE(AH$387,ROW()-2)>AH$388,"",IFERROR(IF(ROW()=2,100,AH9)*INDEX($D$2:$D$428,MATCH(EDATE(AH$387,ROW()-2),$A$2:$A$428,0))/INDEX($D$2:$D$428,MATCH(EDATE(AH$387,ROW()-2),$A$2:$A$428,0)-1),""))} -> 102.77064 | AJ10: 33117 | AK10: 7 | AN10: =IF(EDATE(AN$387,ROW()-2)>AN$388,"",IFERROR((INDEX($AL$2:$AL$441,MATCH(EDATE(AN$387,ROW()-2),$AJ$2:$AJ$441,0))-INDEX($AL$2:$AL$441,MATCH(EDATE(AN$387,-1),$AJ$2:$AJ$441,0)))*100,"")) -> 8.2296192 | AO10: =IF(EDATE(AO$387,ROW()-2)>AO$388,"",IFERROR((INDEX($AL$2:$AL$441,MATCH(EDATE(AO$387,ROW()-2),$AJ$2:$AJ$441,0))-INDEX($AL$2:$AL$441,MATCH(EDATE(AO$387,-1),$AJ$2:$AJ$441,0)))*100,"")) -> -1.7463249 | AP10: =IF(EDATE(AP$387,ROW()-2)>AP$388,"",IFERROR((INDEX($AL$2:$AL$441,MATCH(EDATE(AP$387,ROW()-2),$AJ$2:$AJ$441,0))-INDEX($AL$2:$AL$441,MATCH(EDATE(AP$387,-1),$AJ$2:$AJ$441,0)))*100,"")) -> -2.1341966 | AQ10: =IF(EDATE(AQ$387,ROW()-2)>AQ$388,"",IFERROR((INDEX($AL$2:$AL$441,MATCH(EDATE(AQ$387,ROW()-2),$AJ$2:$AJ$441,0))-INDEX($AL$2:$AL$441,MATCH(EDATE(AQ$387,-1),$AJ$2:$AJ$441,0)))*100,"")) -> -2.4473754 | AR10: =IF(EDATE(AR$387,ROW()-2)>AR$388,"",IFERROR((INDEX($AL$2:$AL$441,MATCH(EDATE(AR$387,ROW()-2),$AJ$2:$AJ$441,0))-INDEX($AL$2:$AL$441,MATCH(EDATE(AR$387,-1),$AJ$2:$AJ$441,0)))*100,"")) -> 8.068512 | AS10: =IF(EDATE(AS$387,ROW()-2)>AS$388,"",IFERROR((INDEX($AL$2:$AL$441,MATCH(EDATE(AS$387,ROW()-2),$AJ$2:$AJ$441,0))-INDEX($AL$2:$AL$441,MATCH(EDATE(AS$387,-1),$AJ$2:$AJ$441,0)))*100,"")) -> 5.648657 | AT10: =IF(EDATE(AT$387,ROW()-2)>AT$388,"",IFERROR((INDEX($AL$2:$AL$441,MATCH(EDATE(AT$387,ROW()-2),$AJ$2:$AJ$441,0))-INDEX($AL$2:$AL$441,MATCH(EDATE(AT$387,-1),$AJ$2:$AJ$441,0)))*100,"")) -> 1.2636172 | AU10: =IF(EDATE(AU$387,ROW()-2)>AU$388,"",IFERROR((INDEX($AL$2:$AL$441,MATCH(EDATE(AU$387,ROW()-2),$AJ$2:$AJ$441,0))-INDEX($AL$2:$AL$441,MATCH(EDATE(AU$387,-1),$AJ$2:$AJ$441,0)))*100,"")) -> -2.823506
A11: 33512 | B11: 11.95 | C11: - | D11: - | E11: =A11 -> 33512 | I11: =A11 -> 33512 | O11: 34973 | P11: {=IF(OR($O11<P$387,$O11>P$388),"",IFERROR(IF($O11=P$387,100,P10)*INDEX($B$2:$B$428,MATCH($O11,$A$2:$A$428,0))/INDEX($B$2:$B$428,MATCH($O11,$A$2:$A$428,0)-1),""))} -> 127.00095 | Q11: {=IF(OR($O11<Q$387,$O11>Q$388),"",IFERROR(IF($O11=Q$387,100,Q10)*INDEX($B$2:$B$428,MATCH($O11,$A$2:$A$428,0))/INDEX($B$2:$B$428,MATCH($O11,$A$2:$A$428,0)-1),""))} | R11: {=IF(OR($O11<R$387,$O11>R$388),"",IFERROR(IF($O11=R$387,100,R10)*INDEX($B$2:$B$428,MATCH($O11,$A$2:$A$428,0))/INDEX($B$2:$B$428,MATCH($O11,$A$2:$A$428,0)-1),""))} | S11: {=IF(OR($O11<S$387,$O11>S$388),"",IFERROR(IF($O11=S$387,100,S10)*INDEX($B$2:$B$428,MATCH($O11,$A$2:$A$428,0))/INDEX($B$2:$B$428,MATCH($O11,$A$2:$A$428,0)-1),""))} | T11: {=IF(OR($O11<T$387,$O11>T$388),"",IFERROR(IF($O11=T$387,100,T10)*INDEX($B$2:$B$428,MATCH($O11,$A$2:$A$428,0))/INDEX($B$2:$B$428,MATCH($O11,$A$2:$A$428,0)-1),""))} | U11: {=IF(OR($O11<U$387,$O11>U$388),"",IFERROR(IF($O11=U$387,100,U10)*INDEX($B$2:$B$428,MATCH($O11,$A$2:$A$428,0))/INDEX($B$2:$B$428,MATCH($O11,$A$2:$A$428,0)-1),""))} | V11: {=IF(OR($O11<V$387,$O11>V$388),"",IFERROR(IF($O11=V$387,100,V10)*INDEX($B$2:$B$428,MATCH($O11,$A$2:$A$428,0))/INDEX($B$2:$B$428,MATCH($O11,$A$2:$A$428,0)-1),""))} | W11: {=IF(OR($O11<W$387,$O11>W$388),"",IFERROR(IF($O11=W$387,100,W10)*INDEX($B$2:$B$428,MATCH($O11,$A$2:$A$428,0))/INDEX($B$2:$B$428,MATCH($O11,$A$2:$A$428,0)-1),""))} | X11: {=IF(OR($O11<X$387,$O11>X$388),"",IFERROR(IF($O11=X$387,100,X10)*INDEX($B$2:$B$428,MATCH($O11,$A$2:$A$428,0))/INDEX($B$2:$B$428,MATCH($O11,$A$2:$A$428,0)-1),""))} | AA11: {=IF(EDATE(AA$387,ROW()-2)>AA$388,"",IFERROR(IF(ROW()=2,100,AA10)*INDEX($D$2:$D$428,MATCH(EDATE(AA$387,ROW()-2),$A$2:$A$428,0))/INDEX($D$2:$D$428,MATCH(EDATE(AA$387,ROW()-2),$A$2:$A$428,0)-1),""))} -> 124.78267 | AB11: {=IF(EDATE(AB$387,ROW()-2)>AB$388,"",IFERROR(IF(ROW()=2,100,AB10)*INDEX($D$2:$D$428,MATCH(EDATE(AB$387,ROW()-2),$A$2:$A$428,0))/INDEX($D$2:$D$428,MATCH(EDATE(AB$387,ROW()-2),$A$2:$A$428,0)-1),""))} -> 108.71442 | AC11: {=IF(EDATE(AC$387,ROW()-2)>AC$388,"",IFERROR(IF(ROW()=2,100,AC10)*INDEX($D$2:$D$428,MATCH(EDATE(AC$387,ROW()-2),$A$2:$A$428,0))/INDEX($D$2:$D$428,MATCH(EDATE(AC$387,ROW()-2),$A$2:$A$428,0)-1),""))} -> 107.8325 | AD11: {=IF(EDATE(AD$387,ROW()-2)>AD$388,"",IFERROR(IF(ROW()=2,100,AD10)*INDEX($D$2:$D$428,MATCH(EDATE(AD$387,ROW()-2),$A$2:$A$428,0))/INDEX($D$2:$D$428,MATCH(EDATE(AD$387,ROW()-2),$A$2:$A$428,0)-1),""))} -> 106.2018 | AE11: {=IF(EDATE(AE$387,ROW()-2)>AE$388,"",IFERROR(IF(ROW()=2,100,AE10)*INDEX($D$2:$D$428,MATCH(EDATE(AE$387,ROW()-2),$A$2:$A$428,0))/INDEX($D$2:$D$428,MATCH(EDATE(AE$387,ROW()-2),$A$2:$A$428,0)-1),""))} -> 113.88604 | AF11: {=IF(EDATE(AF$387,ROW()-2)>AF$388,"",IFERROR(IF(ROW()=2,100,AF10)*INDEX($D$2:$D$428,MATCH(EDATE(AF$387,ROW()-2),$A$2:$A$428,0))/INDEX($D$2:$D$428,MATCH(EDATE(AF$387,ROW()-2),$A$2:$A$428,0)-1),""))} -> 114.63276 | AG11: {=IF(EDATE(AG$387,ROW()-2)>AG$388,"",IFERROR(IF(ROW()=2,100,AG10)*INDEX($D$2:$D$428,MATCH(EDATE(AG$387,ROW()-2),$A$2:$A$428,0))/INDEX($D$2:$D$428,MATCH(EDATE(AG$387,ROW()-2),$A$2:$A$428,0)-1),""))} -> 104.78165 | AH11: {=IF(EDATE(AH$387,ROW()-2)>AH$388,"",IFERROR(IF(ROW()=2,100,AH10)*INDEX($D$2:$D$428,MATCH(EDATE(AH$387,ROW()-2),$A$2:$A$428,0))/INDEX($D$2:$D$428,MATCH(EDATE(AH$387,ROW()-2),$A$2:$A$428,0)-1),""))} -> 103.94569 | AJ11: 33147 | AK11: 8.3 | AN11: =IF(EDATE(AN$387,ROW()-2)>AN$388,"",IFERROR((INDEX($AL$2:$AL$441,MATCH(EDATE(AN$387,ROW()-2),$AJ$2:$AJ$441,0))-INDEX($AL$2:$AL$441,MATCH(EDATE(AN$387,-1),$AJ$2:$AJ$441,0)))*100,"")) -> 9.1746852 | AO11: =IF(EDATE(AO$387,ROW()-2)>AO$388,"",IFERROR((INDEX($AL$2:$AL$441,MATCH(EDATE(AO$387,ROW()-2),$AJ$2:$AJ$441,0))-INDEX($AL$2:$AL$441,MATCH(EDATE(AO$387,-1),$AJ$2:$AJ$441,0)))*100,"")) -> -2.7902761 | AP11: =IF(EDATE(AP$387,ROW()-2)>AP$388,"",IFERROR((INDEX($AL$2:$AL$441,MATCH(EDATE(AP$387,ROW()-2),$AJ$2:$AJ$441,0))-INDEX($AL$2:$AL$441,MATCH(EDATE(AP$387,-1),$AJ$2:$AJ$441,0)))*100,"")) -> -1.8772116 | AQ11: =IF(EDATE(AQ$387,ROW()-2)>AQ$388,"",IFERROR((INDEX($AL$2:$AL$441,MATCH(EDATE(AQ$387,ROW()-2),$AJ$2:$AJ$441,0))-INDEX($AL$2:$AL$441,MATCH(EDATE(AQ$387,-1),$AJ$2:$AJ$441,0)))*100,"")) -> -2.5945518 | AR11: =IF(EDATE(AR$387,ROW()-2)>AR$388,"",IFERROR((INDEX($AL$2:$AL$441,MATCH(EDATE(AR$387,ROW()-2),$AJ$2:$AJ$441,0))-INDEX($AL$2:$AL$441,MATCH(EDATE(AR$387,-1),$AJ$2:$AJ$441,0)))*100,"")) -> 6.3694491 | AS11: =IF(EDATE(AS$387,ROW()-2)>AS$388,"",IFERROR((INDEX($AL$2:$AL$441,MATCH(EDATE(AS$387,ROW()-2),$AJ$2:$AJ$441,0))-INDEX($AL$2:$AL$441,MATCH(EDATE(AS$387,-1),$AJ$2:$AJ$441,0)))*100,"")) -> 7.0563433 | AT11: =IF(EDATE(AT$387,ROW()-2)>AT$388,"",IFERROR((INDEX($AL$2:$AL$441,MATCH(EDATE(AT$387,ROW()-2),$AJ$2:$AJ$441,0))-INDEX($AL$2:$AL$441,MATCH(EDATE(AT$387,-1),$AJ$2:$AJ$441,0)))*100,"")) -> 0.20141071 | AU11: =IF(EDATE(AU$387,ROW()-2)>AU$388,"",IFERROR((INDEX($AL$2:$AL$441,MATCH(EDATE(AU$387,ROW()-2),$AJ$2:$AJ$441,0))-INDEX($AL$2:$AL$441,MATCH(EDATE(AU$387,-1),$AJ$2:$AJ$441,0)))*100,"")) -> -2.4521098
